Workbook

Sheet Scorecard
B2: LilyPad
B4: # | C4: Portfolio | D4: Contact | E4: Company | F4: Initiative | G4: Last Qtr Status | H4: Status | I4: Strategic Value Level | J4: Business Problem Solved | K4: Ratio Impacted | L4: KPI Metric | M4: Financial Target | N4: Financial Actual | O4: Strategic Value Pts | P4: Status Weight | Q4: Progress Value | R4: Total Score
B5: Sample | C5: =IF(F5="","","PYXiS") -> PYXiS | D5: =IF(F5="","",Sample!$C$17) -> jamie.collingwood@pyxissoftware.com | E5: =IF(D5="","",B$2) -> LilyPad | F5: =IF(Sample!$F$3="","",Sample!$F$3) -> Support ticket triage for password resets (SAMPLE) | G5: =IF(F5="","",Sample!$AO$5) -> Dev | H5: =IF(F5="","",Sample!$AO$4) -> Pilot | I5: =Sample!$F$8 -> Internal Process | J5: =Sample!$F$5 -> Enables registered customers to quickly gain access to the code key needed to add a new computer or user to their product. Will ensure that our service records are updated so that next billing cycle increments to match actually users. | K5: =Sample!$AC$7 -> Maintenance | L5: =Sample!$G$13 -> Employee AI Tool Adoption Rate | M5: =Sample!$BE$35*1000 -> 250000 | N5: =Sample!$E$51*1000 -> 0 | O5: =Sample!$AV$3 -> 50 | P5: =Sample!$AV$4 -> 0.7 | Q5: =Sample!$AV$5 -> 1.2 | R5: =O5*P5*Q5 -> 42
B6: 1 | C6: =IF(F6="","","PYXiS") -> PYXiS | D6: =IF(F6="","",'P1'!$C$17) -> ed.leisman@pyxissoftware.com | E6: =IF(F6="","",B$2) -> LilyPad | F6: =IF('P1'!$F$3="","",'P1'!$F$3) -> Natural Language Dashboards | G6: =IF(F6="","",'P1'!$AO$5) -> Idea | H6: =IF(F6="","",'P1'!$AO$4) -> Dev | I6: =IF(F6="","",'P1'!$F$8) -> Customer Feature - New | J6: =IF(F6="","",'P1'!$F$5) -> (Orbit Flow) Analytics enabling customers to better capitalize on business opportunity. | K6: =IF(F6="","",'P1'!$AC$7) -> Maintenance | L6: =IF(F6="","",'P1'!$G$13) -> New AI-enabled Products/Features | M6: ='P1'!$BE$35*1000 -> 10000 | N6: ='P1'!$E$51*1000 -> 0 | O6: ='P1'!$AV$3 -> 200 | P6: ='P1'!$AV$4 -> 0.4 | Q6: ='P1'!$AV$5 -> 1.2 | R6: =O6*P6*Q6 -> 96
B7: 2 | C7: =IF(F7="","","PYXiS") -> PYXiS | D7: =IF(F7="","",'P2'!$C$17) -> ed.leisman@pyxissoftware.com | E7: =IF(F7="","",B$2) -> LilyPad | F7: =IF('P2'!$F$3="","",'P2'!$F$3) -> Claude Code Implementation | G7: =IF(F7="","",'P2'!$AO$5) -> Not Def | H7: =IF(F7="","",'P2'!$AO$4) -> Dev | I7: =IF(F7="","",'P2'!$F$8) -> Complex Tool | J7: =IF(F7="","",'P2'!$F$5) -> Claude Code solves the problem of slow, error-prone development cycles by automating coding and debugging, accelerating delivery timelines, reducing costs, and improving overall developer efficiency and output quality. | K7: =IF(F7="","",'P2'!$AC$7) -> R&D | L7: =IF(F7="","",'P2'!$G$13) -> Employee AI Tool Adoption Rate | M7: ='P2'!$BE$35*1000 -> 0 | N7: ='P2'!$E$51*1000 -> 0 | O7: ='P2'!$AV$3 -> 25 | P7: ='P2'!$AV$4 -> 0.4 | Q7: ='P2'!$AV$5 -> 1.2 | R7: =O7*P7*Q7 -> 12
B8: 3 | C8: =IF(F8="","","PYXiS") | D8: =IF(F8="","",'P3'!$C$17) | E8: =IF(F8="","",B$2) | F8: =IF('P3'!$F$3="","",'P3'!$F$3) | G8: =IF(F8="","",'P3'!$AO$5) | H8: =IF(F8="","",'P3'!$AO$4) | I8: =IF(F8="","",'P3'!$F$8) | J8: =IF(F8="","",'P3'!$F$5) | K8: =IF(F8="","",'P3'!$AC$7) | L8: =IF(F8="","",'P3'!$G$13) | M8: ='P3'!$BE$35*1000 -> 0 | N8: ='P3'!$E$51*1000 -> 0 | O8: ='P3'!$AV$3 -> 0 | P8: ='P3'!$AV$4 -> 0 | Q8: ='P3'!$AV$5 -> 0 | R8: =O8*P8*Q8 -> 0
B9: 4 | C9: =IF(F9="","","PYXiS") | D9: =IF(F9="","",'P4'!$C$17) | E9: =IF(F9="","",B$2) | F9: =IF('P4'!$F$3="","",'P4'!$F$3) | G9: =IF(F9="","",'P4'!$AO$5) | H9: =IF(F9="","",'P4'!$AO$4) | I9: =IF(F9="","",'P4'!$F$8) | J9: =IF(F9="","",'P4'!$F$5) | K9: =IF(F9="","",'P4'!$AC$7) | L9: =IF(F9="","",'P4'!$G$13) | M9: ='P4'!$BE$35*1000 -> 0 | N9: ='P4'!$E$51*1000 -> 0 | O9: ='P4'!$AV$3 -> 0 | P9: ='P4'!$AV$4 -> 0 | Q9: ='P4'!$AV$5 -> 0 | R9: =O9*P9*Q9 -> 0
B10: 5 | C10: =IF(F10="","","PYXiS") | D10: =IF(F10="","",'P5'!$C$17) | E10: =IF(F10="","",B$2) | F10: =IF('P5'!$F$3="","",'P5'!$F$3) | G10: =IF(F10="","",'P5'!$AO$5) | H10: =IF(F10="","",'P5'!$AO$4) | I10: =IF(F10="","",'P5'!$F$8) | J10: =IF(F10="","",'P5'!$F$5) | K10: =IF(F10="","",'P5'!$AC$7) | L10: =IF(F10="","",'P5'!$G$13) | M10: ='P5'!$BE$35*1000 -> 0 | N10: ='P5'!$E$51*1000 -> 0 | O10: ='P5'!$AV$3 -> 0 | P10: ='P5'!$AV$4 -> 0 | Q10: ='P5'!$AV$5 -> 0 | R10: =O10*P47*Q10 -> 0
B11: 6 | C11: =IF(F11="","","PYXiS") | D11: =IF(F11="","",'P6'!$C$17) | E11: =IF(F11="","",B$2) | F11: =IF('P6'!$F$3="","",'P6'!$F$3) | G11: =IF(F11="","",'P6'!$AO$5) | H11: =IF(F11="","",'P6'!$AO$4) | I11: =IF(F11="","",'P6'!$F$8) | J11: =IF(F11="","",'P6'!$F$5) | K11: =IF(F11="","",'P6'!$AC$7) | L11: =IF(F11="","",'P6'!$G$13) | M11: ='P6'!$BE$35*1000 -> 0 | N11: ='P6'!$E$51*1000 -> 0 | O11: ='P6'!$AV$3 -> 0 | P11: ='P6'!$AV$4 -> 0 | Q11: ='P6'!$AV$5 -> 0 | R11: =O11*P58*Q11 -> 0
B12: 7 | C12: =IF(F12="","","PYXiS") | D12: =IF(F12="","",'P7'!$C$17) | E12: =IF(F12="","",B$2) | F12: =IF('P7'!$F$3="","",'P7'!$F$3) | G12: =IF(F12="","",'P7'!$AO$5) | H12: =IF(F12="","",'P7'!$AO$4) | I12: =IF(F12="","",'P7'!$F$8) | J12: =IF(F12="","",'P7'!$F$5) | K12: =IF(F12="","",'P7'!$AC$7) | L12: =IF(F12="","",'P7'!$G$13) | M12: ='P7'!$BE$35*1000 -> 0 | N12: ='P7'!$E$51*1000 -> 0 | O12: ='P7'!$AV$3 -> 0 | P12: ='P7'!$AV$4 -> 0 | Q12: ='P7'!$AV$5 -> 0 | R12: =O12*P69*Q12 -> 0
B13: 8 | C13: =IF(F13="","","PYXiS") | D13: =IF(F13="","",'P8'!$C$17) | E13: =IF(F13="","",B$2) | F13: =IF('P8'!$F$3="","",'P8'!$F$3) | G13: =IF(F13="","",'P8'!$AO$5) | H13: =IF(F13="","",'P8'!$AO$4) | I13: =IF(F13="","",'P8'!$F$8) | J13: =IF(F13="","",'P8'!$F$5) | K13: =IF(F13="","",'P8'!$AC$7) | L13: =IF(F13="","",'P8'!$G$13) | M13: ='P8'!$BE$35*1000 -> 0 | N13: ='P8'!$E$51*1000 -> 0 | O13: ='P8'!$AV$3 -> 0 | P13: ='P8'!$AV$4 -> 0 | Q13: ='P8'!$AV$5 -> 0 | R13: =O13*P80*Q13 -> 0
B14: 9 | C14: =IF(F14="","","PYXiS") | D14: =IF(F14="","",'P9'!$C$17) | E14: =IF(F14="","",B$2) | F14: =IF('P9'!$F$3="","",'P9'!$F$3) | G14: =IF(F14="","",'P9'!$AO$5) | H14: =IF(F14="","",'P9'!$AO$4) | I14: =IF(F14="","",'P9'!$F$8) | J14: =IF(F14="","",'P9'!$F$5) | K14: =IF(F14="","",'P9'!$AC$7) | L14: =IF(F14="","",'P9'!$G$13) | M14: ='P9'!$BE$35*1000 -> 0 | N14: ='P9'!$E$51*1000 -> 0 | O14: ='P9'!$AV$3 -> 0 | P14: ='P9'!$AV$4 -> 0 | Q14: ='P9'!$AV$5 -> 0 | R14: =O14*P91*Q14 -> 0
B15: 10 | C15: =IF(F15="","","PYXiS") | D15: =IF(F15="","",'P10'!$C$17) | E15: =IF(F15="","",B$2) | F15: =IF('P10'!$F$3="","",'P10'!$F$3) | G15: =IF(F15="","",'P10'!$AO$5) | H15: =IF(F15="","",'P10'!$AO$4) | I15: =IF(F15="","",'P10'!$F$8) | J15: =IF(F15="","",'P10'!$F$5) | K15: =IF(F15="","",'P10'!$AC$7) | L15: =IF(F15="","",'P10'!$G$13) | M15: ='P10'!$BE$35*1000 -> 0 | N15: ='P10'!$E$51*1000 -> 0 | O15: ='P10'!$AV$3 -> 0 | P15: ='P10'!$AV$4 -> 0 | Q15: ='P10'!$AV$5 -> 0 | R15: =O15*P102*Q15 -> 0
L16: TOTAL FINANCIAL | M16: =SUM(M6:M15) -> 10000 | N16: =SUM(N6:N15) -> 0 | O16: TOTAL AI SCORE FOR BU | R16: =SUM(R6:R15) -> 108
B17: Complete all sections in yellow
B19: Cells in this color are free form text
B21: Cells in this color are limited to the drop down values provided
B23: This is a sample and can be deleted.
B25: Inout all values in $'000s

Sheet Sample
B3: PROJECT | F3: Support ticket triage for password resets (SAMPLE) | AG3: Strategic Value | AO3: =F8 -> Internal Process | AV3: =IF(F7="",0,VLOOKUP(F7,Lookups!B4:H8,3)) -> 50 | AZ3: =NOW() -> 45961.687
AG4: Stage Multiplier (today) | AO4: =VLOOKUP(COUNTIF(AR10:AT21,"<="&AZ3),Table3357[],2) -> Pilot | AV4: =VLOOKUP(AO4,Lookups!L4:M8,2) -> 0.7 | AZ4: Current Qtr | BC4: =VLOOKUP((YEAR(AZ3)&"-"&MONTH(AZ3)),Lookups!S3:U21,2) -> 2025-Q4
B5: Description (Use Case) | F5: Enables registered customers to quickly gain access to the code key needed to add a new computer or user to their product. Will ensure that our service records are updated so that next billing cycle increments to match actually users. | AG5: Stage Last Quarter | AO5: =VLOOKUP(COUNTIF(AR10:AT21,"<"&VLOOKUP(BC4,Lookups!W3:Y9,2)),Table3357[],2) -> Dev | AQ5: =IF(AV5=1,"No Change","Progression") -> Progression | AV5: =IF(AO5=AO4,1,1.2) -> 1.2
AG6: PROJECT SCORE | AV6: =AV3*AV4*AV5 -> 42
B7: Category | F7: L3. AI-powered internal business process improvements | Y7: Ratio Impacted | AC7: Maintenance
B8: Strategic Value Level | F8: =IF(F7="","",VLOOKUP(F7,Lookups!B4:H8,2)) -> Internal Process
B9: Examples | F9: =IF(F7="","",VLOOKUP(F7,Lookups!B4:H8,4)) -> Automated customer support triage, intelligent lead scoring, predictive maintenance, churn analysis, scheduling | AG9: Stage | AJ9: Tasks | AO9: Target | AR9: Completed | AU9: Days to Target | AY9: Notes
AG10: Idea | AJ10: Project Defined | AO10: 45884 | AR10: =AO10 -> 45884 | AU10: =IF(AO10=$BK$3,"Missing Target",IF(AR10=$BK$3,IF($AZ$3>AO10,INT($AZ$3-AO10)&" Day(s) Overdue","Incomplete"),IF(AR10>AO10,INT(AR10-AO10)&" Day(s) Late",IF(AR10=AO10,"OK",INT(AO10-AR10)&" Day(s) Ahead")))) -> OK
B11: PROJECT RESOURCES | F11: KEY PERFORMANCE INDICATORS / MEASURES OF SUCCESS | AJ11: Business Case approved | AO11: =AO10+7 -> 45891 | AR11: =AO11 -> 45891 | AU11: =IF(AO11=$BK$3,"Missing Target",IF(AR11=$BK$3,IF($AZ$3>AO11,INT($AZ$3-AO11)&" Day(s) Overdue","Incomplete"),IF(AR11>AO11,INT(AR11-AO11)&" Day(s) Late",IF(AR11=AO11,"OK",INT(AO11-AR11)&" Day(s) Ahead")))) -> OK
B12: AI Tools & Services | F12: =IF(F7="","",VLOOKUP(F7,Lookups!B4:H8,5)) -> Employee Satisfaction | O12: =IF(F7="","",VLOOKUP(F7,Lookups!B4:H8,6)) -> Productivity Gains | X12: =IF(F7="","",VLOOKUP(F7,Lookups!B4:H8,7)) -> Cost Savings | AJ12: Resources Allocated | AO12: =AO11+7 -> 45898 | AR12: =AO12 -> 45898 | AU12: =IF(AO12=$BK$3,"Missing Target",IF(AR12=$BK$3,IF($AZ$3>AO12,INT($AZ$3-AO12)&" Day(s) Overdue","Incomplete"),IF(AR12>AO12,INT(AR12-AO12)&" Day(s) Late",IF(AR12=AO12,"OK",INT(AO12-AR12)&" Day(s) Ahead")))) -> OK
B13: OrbitAI combined with IRIS AI. | F13: KPI | G13: Employee AI Tool Adoption Rate | O13: KPI | P13: Customer Satisfaction Scores (CSAT, NPS) | X13: KPI | Y13: Cost Savings | AG13: Develop | AJ13: Technical PoC validated | AO13: =AO12+7 -> 45905 | AR13: =AO13+2 -> 45907 | AU13: =IF(AO13=$BK$3,"Missing Target",IF(AR13=$BK$3,IF($AZ$3>AO13,INT($AZ$3-AO13)&" Day(s) Overdue","Incomplete"),IF(AR13>AO13,INT(AR13-AO13)&" Day(s) Late",IF(AR13=AO13,"OK",INT(AO13-AR13)&" Day(s) Ahead")))) -> 2 Day(s) Late
F14: How does this Project support this KPI? | O14: How does this Project support this KPI? | X14: How does this Project support this KPI? | AJ14: Dev roadmap documented | AO14: =AO13+7 -> 45912 | AR14: =AO14+7 -> 45919 | AU14: =IF(AO14=$BK$3,"Missing Target",IF(AR14=$BK$3,IF($AZ$3>AO14,INT($AZ$3-AO14)&" Day(s) Overdue","Incomplete"),IF(AR14>AO14,INT(AR14-AO14)&" Day(s) Late",IF(AR14=AO14,"OK",INT(AO14-AR14)&" Day(s) Ahead")))) -> 7 Day(s) Late
F15: The solution will enable customer support resources to concentrate their time to work on more complex problems which will driver more job satisfaction. | O15: If the Agent is able to respond quickly and accurately 24x7 to these requests customers should be very happy with this increases speed of response. | X15: Shifting low-IP tasks to an Agent will allow us to free up skilled representatives to spend more time on customers and tickets that need specialist attention. Our serbvice capacity will grow faster than OPEX and drive improvements to our MR. | AJ15: Coding started | AO15: =AO14+7 -> 45919 | AR15: =AR14 -> 45919 | AU15: =IF(AO15=$A$1,"Missing Target",IF(AR15=$A$1,IF($AZ$3>AO15,INT($AZ$3-AO15)&" Day(s) Overdue","Incomplete"),IF(AR15>AO15,INT(AR15-AO15)&" Day(s) Late",IF(AR15=AO15,"OK",INT(AO15-AR15)&" Day(s) Ahead")))) -> OK
AG16: Pilot | AJ16: Deployment to beta | AO16: =AO15+7 -> 45926 | AR16: 45931 | AU16: =IF(AO16=$A$1,"Missing Target",IF(AR16=$A$1,IF($AZ$3>AO16,INT($AZ$3-AO16)&" Day(s) Overdue","Incomplete"),IF(AR16>AO16,INT(AR16-AO16)&" Day(s) Late",IF(AR16=AO16,"OK",INT(AO16-AR16)&" Day(s) Ahead")))) -> 5 Day(s) Late
B17: Contact | C17: jamie.collingwood@pyxissoftware.com | AJ17: Initial metrics/feedback | AO17: =AO16+7 -> 45933 | AU17: =IF(AO17=$A$1,"Missing Target",IF(AR17=$A$1,IF($AZ$3>AO17,INT($AZ$3-AO17)&" Day(s) Overdue","Incomplete"),IF(AR17>AO17,INT(AR17-AO17)&" Day(s) Late",IF(AR17=AO17,"OK",INT(AO17-AR17)&" Day(s) Ahead")))) -> 28 Day(s) Overdue
B18: Prod Mgr | C18: Jamie Collingwood | F18: How will you measure the KPI? | O18: How will you measure the KPI? | X18: How will you measure the KPI? | AJ18: Feedback affecting code | AO18: =AO17+7 -> 45940 | AU18: =IF(AO18=$A$1,"Missing Target",IF(AR18=$A$1,IF($AZ$3>AO18,INT($AZ$3-AO18)&" Day(s) Overdue","Incomplete"),IF(AR18>AO18,INT(AR18-AO18)&" Day(s) Late",IF(AR18=AO18,"OK",INT(AO18-AR18)&" Day(s) Ahead")))) -> 21 Day(s) Overdue
B19: Analyst | C19: Chase Winston | F19: Staff Satisfaction surveys will be conducted as we introduce the Agent and train it to work on, first, Low-IP tasks, and provide copilot support to the support representatives. Sat / 100, lifitng from current scre of 55 to a target of 80 in Q1 2026. | O19: We will track calls / Agent v calls / Rep and we will ask all callers working with the Agent to leave a short feedback note/rating to determine if this improves their perception of the service. | X19: Ticket count satisfactorily closed by Agent / Rep will be measures alongside the ticket count / costs to identify if the two are closely correlated. MR to increase from 5.2 to 7 by Q2 2026, equivelent to $250,000 OPEX saving. | AG19: Live | AJ19: General release available | AO19: =AO18+7 -> 45947 | AU19: =IF(AO19=$A$1,"Missing Target",IF(AR19=$A$1,IF($AZ$3>AO19,INT($AZ$3-AO19)&" Day(s) Overdue","Incomplete"),IF(AR19>AO19,INT(AR19-AO19)&" Day(s) Late",IF(AR19=AO19,"OK",INT(AO19-AR19)&" Day(s) Ahead")))) -> 14 Day(s) Overdue
B20: Tech Lead | C20: Jim Peltier | AJ20: Success metrics tracking | AO20: =AO19+7 -> 45954 | AU20: =IF(AO20=$A$1,"Missing Target",IF(AR20=$A$1,IF($AZ$3>AO20,INT($AZ$3-AO20)&" Day(s) Overdue","Incomplete"),IF(AR20>AO20,INT(AR20-AO20)&" Day(s) Late",IF(AR20=AO20,"OK",INT(AO20-AR20)&" Day(s) Ahead")))) -> 7 Day(s) Overdue
B21: Exec | C21: Sandy Crutcher | AJ21: Feedback loop continuing | AU21: =IF(AO21=$A$1,"Missing Target",IF(AR21=$A$1,IF($AZ$3>AO21,INT($AZ$3-AO21)&" Day(s) Overdue","Incomplete"),IF(AR21>AO21,INT(AR21-AO21)&" Day(s) Late",IF(AR21=AO21,"OK",INT(AO21-AR21)&" Day(s) Ahead")))) -> Missing Target
B23: WEEKLY KPI TRACKER | F23: 1 | G23: =F23+1 -> 2 | H23: =G23+1 -> 3 | I23: =H23+1 -> 4 | J23: =I23+1 -> 5 | K23: =J23+1 -> 6 | L23: =K23+1 -> 7 | M23: =L23+1 -> 8 | N23: =M23+1 -> 9 | ... BE23: =BD23+1 -> 52
B24: Week Ending | F24: 45945 | G24: =F24+7 -> 45952 | H24: =G24+7 -> 45959 | I24: =H24+7 -> 45966 | J24: =I24+7 -> 45973 | K24: =J24+7 -> 45980 | L24: =K24+7 -> 45987 | M24: =L24+7 -> 45994 | N24: =M24+7 -> 46001 | ... BE24: =BD24+7 -> 46302
B25: =G13&" TARGET" -> Employee AI Tool Adoption Rate TARGET | F25: 55 | G25: =F25 -> 55 | H25: =G25 -> 55 | I25: =H25 -> 55 | J25: =I25 -> 55 | K25: =J25 -> 55 | L25: =K25 -> 55 | M25: =L25 -> 55 | N25: 60 | O25: 60 | P25: 65 | Q25: 65 | R25: 66 | S25: 67 | T25: 68 | U25: 69 | V25: 70 | W25: 71 | X25: 72 | Y25: 73 | Z25: 74 | AA25: 75 | AB25: 76 | AC25: 77 | AD25: 78 | AE25: 79 | AF25: 80 | AG25: 80 | AH25: 80 | AI25: 80 | AJ25: 80 | AK25: 80 | AL25: 80 | AM25: 80 | AN25: 80 | AO25: 80 | AP25: 80 | AQ25: 80 | AR25: 80 | AS25: 80 | AT25: 80 | AU25: 80 | AV25: 80 | AW25: 80 | AX25: 80 | AY25: 80 | AZ25: 80 | BA25: 80 | BB25: 80 | BC25: 80 | BD25: 80 | BE25: 80
B26: Actual
B27: Delta | F27: =F26-F25 -> -55 | G27: =G26-G25 -> -55 | H27: =H26-H25 -> -55 | I27: =I26-I25 -> -55 | J27: =J26-J25 -> -55 | K27: =K26-K25 -> -55 | L27: =L26-L25 -> -55 | M27: =M26-M25 -> -55 | ... BE27: =BE26-BE25 -> -80
B28: Notes on this KPI (anything to add this week?)
B30: =P13&" TARGET" -> Customer Satisfaction Scores (CSAT, NPS) TARGET | F30: 80 | G30: =F30 -> 80 | H30: =G30 -> 80 | I30: =H30 -> 80 | J30: =I30 -> 80 | K30: =J30 -> 80 | L30: =K30 -> 80 | M30: =L30 -> 80 | N30: =M30 -> 80 | ... BE30: =BD30 -> 80
B31: Actual
B32: Delta | F32: =F31-F30 -> -80 | G32: =G31-G30 -> -80 | H32: =H31-H30 -> -80 | I32: =I31-I30 -> -80 | J32: =J31-J30 -> -80 | K32: =K31-K30 -> -80 | L32: =L31-L30 -> -80 | M32: =M31-M30 -> -80 | ... BE32: =BE31-BE30 -> -80
B33: Notes on this KPI (anything to add this week?)
B35: =Y13&" TARGET" -> Cost Savings TARGET | F35: 250 | G35: =F35 -> 250 | H35: =G35 -> 250 | I35: =H35 -> 250 | J35: =I35 -> 250 | K35: =J35 -> 250 | L35: =K35 -> 250 | M35: =L35 -> 250 | N35: =M35 -> 250 | ... BE35: =BD35 -> 250
B36: Actual | F36: 0 | G36: 0 | H36: 0 | I36: 0 | J36: 0 | K36: 0 | L36: 0 | M36: 0
B37: Delta | F37: =F36-F35 -> -250 | G37: =G36-G35 -> -250 | H37: =H36-H35 -> -250 | I37: =I36-I35 -> -250 | J37: =J36-J35 -> -250 | K37: =K36-K35 -> -250 | L37: =L36-L35 -> -250 | M37: =M36-M35 -> -250 | ... BE37: =BE36-BE35 -> -250
B38: Notes on this KPI (anything to add this week?)
B41: Revenue Target | F41: =IF($X$12="Revenue Impact",F35,0) -> 0 | G41: =IF($X$12="Revenue Impact",G35,0) -> 0 | H41: =IF($X$12="Revenue Impact",H35,0) -> 0 | I41: =IF($X$12="Revenue Impact",I35,0) -> 0 | J41: =IF($X$12="Revenue Impact",J35,0) -> 0 | K41: =IF($X$12="Revenue Impact",K35,0) -> 0 | L41: =IF($X$12="Revenue Impact",L35,0) -> 0 | M41: =IF($X$12="Revenue Impact",M35,0) -> 0 | ... BE41: =IF($X$12="Revenue Impact",BE35,0) -> 0
B42: Revenue Actual | F42: =IF($X$12="Revenue Impact",F36,0) -> 0 | G42: =IF($X$12="Revenue Impact",G36,0) -> 0 | H42: =IF($X$12="Revenue Impact",H36,0) -> 0 | I42: =IF($X$12="Revenue Impact",I36,0) -> 0 | J42: =IF($X$12="Revenue Impact",J36,0) -> 0 | K42: =IF($X$12="Revenue Impact",K36,0) -> 0 | L42: =IF($X$12="Revenue Impact",L36,0) -> 0 | M42: =IF($X$12="Revenue Impact",M36,0) -> 0 | ... BE42: =IF($X$12="Revenue Impact",BE36,0) -> 0
B44: Cost Target | F44: =IF($X$12="Cost Savings",F35,0) -> 250 | G44: =IF($X$12="Cost Savings",G35,0) -> 250 | H44: =IF($X$12="Cost Savings",H35,0) -> 250 | I44: =IF($X$12="Cost Savings",I35,0) -> 250 | J44: =IF($X$12="Cost Savings",J35,0) -> 250 | K44: =IF($X$12="Cost Savings",K35,0) -> 250 | L44: =IF($X$12="Cost Savings",L35,0) -> 250 | M44: =IF($X$12="Cost Savings",M35,0) -> 250 | ... BE44: =IF($X$12="Cost Savings",BE35,0) -> 250
B45: Cost Actual | F45: =IF($X$12="Cost Savings",F36,0) -> 0 | G45: =IF($X$12="Cost Savings",G36,0) -> 0 | H45: =IF($X$12="Cost Savings",H36,0) -> 0 | I45: =IF($X$12="Cost Savings",I36,0) -> 0 | J45: =IF($X$12="Cost Savings",J36,0) -> 0 | K45: =IF($X$12="Cost Savings",K36,0) -> 0 | L45: =IF($X$12="Cost Savings",L36,0) -> 0 | M45: =IF($X$12="Cost Savings",M36,0) -> 0 | ... BE45: =IF($X$12="Cost Savings",BE36,0) -> 0
B47: Financial Target | F47: =F41+F44 -> 250 | G47: =G41+G44 -> 250 | H47: =H41+H44 -> 250 | I47: =I41+I44 -> 250 | J47: =J41+J44 -> 250 | K47: =K41+K44 -> 250 | L47: =L41+L44 -> 250 | M47: =M41+M44 -> 250 | ... BE47: =BE41+BE44 -> 250
B48: Financial Actual | F48: =F42+F45 -> 0 | G48: =G42+G45 -> 0 | H48: =H42+H45 -> 0 | I48: =I42+I45 -> 0 | J48: =J42+J45 -> 0 | K48: =K42+K45 -> 0 | L48: =L42+L45 -> 0 | M48: =M42+M45 -> 0 | ... BE48: =BE42+BE45 -> 0
E49: To Date
...

Sheet P1
B3: PROJECT | F3: Natural Language Dashboards | AG3: Strategic Value | AO3: =F8 -> Customer Feature - New | AV3: =IF(F7="",0,VLOOKUP(F7,Lookups!B4:H8,3)) -> 200 | AZ3: =NOW() -> 45961.687
AG4: Stage Multiplier (today) | AO4: =VLOOKUP(COUNTIF(AR10:AT21,"<="&AZ3),Table3357[],2) -> Dev | AV4: =IF(AO4="Not Def",0,VLOOKUP(AO4,Lookups!L4:M8,2)) -> 0.4 | AZ4: Current Qtr | BC4: =VLOOKUP((YEAR(AZ3)&"-"&MONTH(AZ3)),Lookups!S3:U21,2) -> 2025-Q4
B5: Description (Use Case) | F5: (Orbit Flow) Analytics enabling customers to better capitalize on business opportunity. | AG5: Stage Last Quarter | AO5: =VLOOKUP(COUNTIF(AR10:AT21,"<"&VLOOKUP(BC4,Lookups!W3:Y9,2)),Table3357[],2) -> Idea | AQ5: =IF(AV5=1,"No Change","Progression") -> Progression | AV5: =IF(AO4="Not Def",0,IF(AO5=AO4,1,1.2)) -> 1.2
AG6: PROJECT SCORE | AV6: =AV3*AV4*AV5 -> 96
B7: Category | F7: L5. Entirely new product capabilities powered by AI | Y7: Ratio Impacted | AC7: Maintenance
B8: Strategic Value Level | F8: =IF(F7="","",VLOOKUP(F7,Lookups!B4:H8,2)) -> Customer Feature - New
B9: Examples | F9: =IF(F7="","",VLOOKUP(F7,Lookups!B4:H8,4)) -> Predictive analytics modules, AI-powered workflow automation, intelligent decision support systems | AG9: Stage | AJ9: Tasks | AO9: Target | AR9: Completed | AU9: Days to Target | AY9: Notes
AG10: Idea | AJ10: Project Defined | AO10: 45929 | AR10: 45929 | AU10: =IF(AO10=$BK$3,"Missing Target",IF(AR10=$BK$3,IF($AZ$3>AO10,INT($AZ$3-AO10)&" Day(s) Overdue","Incomplete"),IF(AR10>AO10,INT(AR10-AO10)&" Day(s) Late",IF(AR10=AO10,"OK",INT(AO10-AR10)&" Day(s) Ahead")))) -> OK
B11: PROJECT RESOURCES | F11: KEY PERFORMANCE INDICATORS / MEASURES OF SUCCESS | AJ11: Business Case approved | AO11: 45936 | AR11: 45936 | AU11: =IF(AO11=$BK$3,"Missing Target",IF(AR11=$BK$3,IF($AZ$3>AO11,INT($AZ$3-AO11)&" Day(s) Overdue","Incomplete"),IF(AR11>AO11,INT(AR11-AO11)&" Day(s) Late",IF(AR11=AO11,"OK",INT(AO11-AR11)&" Day(s) Ahead")))) -> OK
B12: AI Tools & Services | F12: =IF(F7="","",VLOOKUP(F7,Lookups!B4:H8,5)) -> Market Differentiation | O12: =IF(F7="","",VLOOKUP(F7,Lookups!B4:H8,6)) -> Competitive Advantage | X12: =IF(F7="","",VLOOKUP(F7,Lookups!B4:H8,7)) -> Revenue Impact | AJ12: Resources Allocated | AO12: 45938 | AR12: 45938 | AU12: =IF(AO12=$BK$3,"Missing Target",IF(AR12=$BK$3,IF($AZ$3>AO12,INT($AZ$3-AO12)&" Day(s) Overdue","Incomplete"),IF(AR12>AO12,INT(AR12-AO12)&" Day(s) Late",IF(AR12=AO12,"OK",INT(AO12-AR12)&" Day(s) Ahead")))) -> OK
B13: Orbit Framework Claude Code | F13: KPI | G13: New AI-enabled Products/Features | O13: KPI | P13: Successful Adaptation to New Use Cases | X13: KPI | Y13: Conversion Rates from AI-powered features | AG13: Develop | AJ13: Technical PoC validated | AO13: 45939 | AR13: 45939 | AU13: =IF(AO13=$BK$3,"Missing Target",IF(AR13=$BK$3,IF($AZ$3>AO13,INT($AZ$3-AO13)&" Day(s) Overdue","Incomplete"),IF(AR13>AO13,INT(AR13-AO13)&" Day(s) Late",IF(AR13=AO13,"OK",INT(AO13-AR13)&" Day(s) Ahead")))) -> OK
F14: How does this Project support this KPI? | O14: How does this Project support this KPI? | X14: How does this Project support this KPI? | AJ14: Dev roadmap documented | AO14: 45940 | AR14: 45940 | AU14: =IF(AO14=$BK$3,"Missing Target",IF(AR14=$BK$3,IF($AZ$3>AO14,INT($AZ$3-AO14)&" Day(s) Overdue","Incomplete"),IF(AR14>AO14,INT(AR14-AO14)&" Day(s) Late",IF(AR14=AO14,"OK",INT(AO14-AR14)&" Day(s) Ahead")))) -> OK
F15: Delivers a net-new AI capability that does not exist in our product today, enhancing customer value and market positioning. | O15: Delivers adaptable AI capabilities that scale to new use cases and functions, strengthening our competitive position. | X15: Uses AI-driven insights and recommendations to drive higher-value customer actions and improve business outcomes. | AJ15: Coding started | AO15: 45946 | AR15: 45946 | AU15: =IF(AO15=$A$1,"Missing Target",IF(AR15=$A$1,IF($AZ$3>AO15,INT($AZ$3-AO15)&" Day(s) Overdue","Incomplete"),IF(AR15>AO15,INT(AR15-AO15)&" Day(s) Late",IF(AR15=AO15,"OK",INT(AO15-AR15)&" Day(s) Ahead")))) -> OK
AG16: Pilot | AJ16: Deployment to beta | AU16: =IF(AO16=$A$1,"Missing Target",IF(AR16=$A$1,IF($AZ$3>AO16,INT($AZ$3-AO16)&" Day(s) Overdue","Incomplete"),IF(AR16>AO16,INT(AR16-AO16)&" Day(s) Late",IF(AR16=AO16,"OK",INT(AO16-AR16)&" Day(s) Ahead")))) -> Missing Target
B17: Contact | C17: ed.leisman@pyxissoftware.com | AJ17: Initial metrics/feedback | AU17: =IF(AO17=$A$1,"Missing Target",IF(AR17=$A$1,IF($AZ$3>AO17,INT($AZ$3-AO17)&" Day(s) Overdue","Incomplete"),IF(AR17>AO17,INT(AR17-AO17)&" Day(s) Late",IF(AR17=AO17,"OK",INT(AO17-AR17)&" Day(s) Ahead")))) -> Missing Target
B18: Prod Mgr | C18: AJ Huey | F18: How will you measure the KPI? | O18: How will you measure the KPI? | X18: How will you measure the KPI? | AJ18: Feedback affecting code | AU18: =IF(AO18=$A$1,"Missing Target",IF(AR18=$A$1,IF($AZ$3>AO18,INT($AZ$3-AO18)&" Day(s) Overdue","Incomplete"),IF(AR18>AO18,INT(AR18-AO18)&" Day(s) Late",IF(AR18=AO18,"OK",INT(AO18-AR18)&" Day(s) Ahead")))) -> Missing Target
B19: Analyst | C19: AJ Huey | F19: Feature activation rate (% of eligible users who begin using this feature). Target: ≥50% activation within 90 days of launch. | O19: Time required to expand this feature to a new use case. Target: ≤10 days to deliver the first expansion use case. | X19: Conversion rate lift attributable to this feature vs. pre-launch baseline. Target: 10–20% uplift within 6–12 months. | AG19: Live | AJ19: General release available | AU19: =IF(AO19=$A$1,"Missing Target",IF(AR19=$A$1,IF($AZ$3>AO19,INT($AZ$3-AO19)&" Day(s) Overdue","Incomplete"),IF(AR19>AO19,INT(AR19-AO19)&" Day(s) Late",IF(AR19=AO19,"OK",INT(AO19-AR19)&" Day(s) Ahead")))) -> Missing Target
B20: Tech Lead | C20: Arthur Souza | AJ20: Success metrics tracking | AU20: =IF(AO20=$A$1,"Missing Target",IF(AR20=$A$1,IF($AZ$3>AO20,INT($AZ$3-AO20)&" Day(s) Overdue","Incomplete"),IF(AR20>AO20,INT(AR20-AO20)&" Day(s) Late",IF(AR20=AO20,"OK",INT(AO20-AR20)&" Day(s) Ahead")))) -> Missing Target
B21: Exec | C21: Jason Stroud | AJ21: Feedback loop continuing | AU21: =IF(AO21=$A$1,"Missing Target",IF(AR21=$A$1,IF($AZ$3>AO21,INT($AZ$3-AO21)&" Day(s) Overdue","Incomplete"),IF(AR21>AO21,INT(AR21-AO21)&" Day(s) Late",IF(AR21=AO21,"OK",INT(AO21-AR21)&" Day(s) Ahead")))) -> Missing Target
B23: WEEKLY KPI TRACKER | F23: 1 | G23: =F23+1 -> 2 | H23: =G23+1 -> 3 | I23: =H23+1 -> 4 | J23: =I23+1 -> 5 | K23: =J23+1 -> 6 | L23: =K23+1 -> 7 | M23: =L23+1 -> 8 | N23: =M23+1 -> 9 | ... BE23: =BD23+1 -> 52
B24: Week Ending | F24: 45929 | G24: =F24+7 -> 45936 | H24: =G24+7 -> 45943 | I24: =H24+7 -> 45950 | J24: =I24+7 -> 45957 | K24: =J24+7 -> 45964 | L24: =K24+7 -> 45971 | M24: =L24+7 -> 45978 | N24: =M24+7 -> 45985 | ... BE24: =BD24+7 -> 46286
B25: =G13&" TARGET" -> New AI-enabled Products/Features TARGET | F25: 50 | G25: =F25 -> 50 | H25: =G25 -> 50 | I25: =H25 -> 50 | J25: =I25 -> 50 | K25: =J25 -> 50 | L25: =K25 -> 50 | M25: =L25 -> 50 | N25: =M25 -> 50 | ... BE25: =BD25 -> 50
B26: Actual | F26: 0 | G26: 0 | H26: 0 | I26: 0 | J26: 0
B27: Delta | F27: =F26-F25 -> -50 | G27: =G26-G25 -> -50 | H27: =H26-H25 -> -50 | I27: =I26-I25 -> -50 | J27: =J26-J25 -> -50 | K27: =K26-K25 -> -50 | L27: =L26-L25 -> -50 | M27: =M26-M25 -> -50 | ... BE27: =BE26-BE25 -> -50
B28: Notes on this KPI (anything to add this week?) | F28: KPI Baselines TBD
B30: =P13&" TARGET" -> Successful Adaptation to New Use Cases TARGET | F30: 10 | G30: =F30 -> 10 | H30: =G30 -> 10 | I30: =H30 -> 10 | J30: =I30 -> 10 | K30: =J30 -> 10 | L30: =K30 -> 10 | M30: =L30 -> 10 | N30: =M30 -> 10 | ... BE30: =BD30 -> 10
B31: Actual
B32: Delta | F32: =F31-F30 -> -10 | G32: =G31-G30 -> -10 | H32: =H31-H30 -> -10 | I32: =I31-I30 -> -10 | J32: =J31-J30 -> -10 | K32: =K31-K30 -> -10 | L32: =L31-L30 -> -10 | M32: =M31-M30 -> -10 | ... BE32: =BE31-BE30 -> -10
B33: Notes on this KPI (anything to add this week?) | F33: KPI Baselines TBD
B35: =Y13&" TARGET" -> Conversion Rates from AI-powered features TARGET | F35: 10 | G35: =F35 -> 10 | H35: =G35 -> 10 | I35: =H35 -> 10 | J35: =I35 -> 10 | K35: =J35 -> 10 | L35: =K35 -> 10 | M35: =L35 -> 10 | N35: =M35 -> 10 | ... BE35: =BD35 -> 10
B36: Actual | F36: 0 | G36: 0 | H36: 0 | I36: 0 | J36: 0 | K36: 0 | L36: 0 | M36: 0
B37: Delta | F37: =F36-F35 -> -10 | G37: =G36-G35 -> -10 | H37: =H36-H35 -> -10 | I37: =I36-I35 -> -10 | J37: =J36-J35 -> -10 | K37: =K36-K35 -> -10 | L37: =L36-L35 -> -10 | M37: =M36-M35 -> -10 | ... BE37: =BE36-BE35 -> -10
B38: Notes on this KPI (anything to add this week?) | F38: KPI Baselines TBD
B41: Revenue Target | F41: =IF($X$12="Revenue Impact",F35,0) -> 10 | G41: =IF($X$12="Revenue Impact",G35,0) -> 10 | H41: =IF($X$12="Revenue Impact",H35,0) -> 10 | I41: =IF($X$12="Revenue Impact",I35,0) -> 10 | J41: =IF($X$12="Revenue Impact",J35,0) -> 10 | K41: =IF($X$12="Revenue Impact",K35,0) -> 10 | L41: =IF($X$12="Revenue Impact",L35,0) -> 10 | M41: =IF($X$12="Revenue Impact",M35,0) -> 10 | ... BE41: =IF($X$12="Revenue Impact",BE35,0) -> 10
B42: Revenue Actual | F42: =IF($X$12="Revenue Impact",F36,0) -> 0 | G42: =IF($X$12="Revenue Impact",G36,0) -> 0 | H42: =IF($X$12="Revenue Impact",H36,0) -> 0 | I42: =IF($X$12="Revenue Impact",I36,0) -> 0 | J42: =IF($X$12="Revenue Impact",J36,0) -> 0 | K42: =IF($X$12="Revenue Impact",K36,0) -> 0 | L42: =IF($X$12="Revenue Impact",L36,0) -> 0 | M42: =IF($X$12="Revenue Impact",M36,0) -> 0 | ... BE42: =IF($X$12="Revenue Impact",BE36,0) -> 0
B44: Cost Target | F44: =IF($X$12="Cost Savings",F35,0) -> 0 | G44: =IF($X$12="Cost Savings",G35,0) -> 0 | H44: =IF($X$12="Cost Savings",H35,0) -> 0 | I44: =IF($X$12="Cost Savings",I35,0) -> 0 | J44: =IF($X$12="Cost Savings",J35,0) -> 0 | K44: =IF($X$12="Cost Savings",K35,0) -> 0 | L44: =IF($X$12="Cost Savings",L35,0) -> 0 | M44: =IF($X$12="Cost Savings",M35,0) -> 0 | ... BE44: =IF($X$12="Cost Savings",BE35,0) -> 0
B45: Cost Actual | F45: =IF($X$12="Cost Savings",F36,0) -> 0 | G45: =IF($X$12="Cost Savings",G36,0) -> 0 | H45: =IF($X$12="Cost Savings",H36,0) -> 0 | I45: =IF($X$12="Cost Savings",I36,0) -> 0 | J45: =IF($X$12="Cost Savings",J36,0) -> 0 | K45: =IF($X$12="Cost Savings",K36,0) -> 0 | L45: =IF($X$12="Cost Savings",L36,0) -> 0 | M45: =IF($X$12="Cost Savings",M36,0) -> 0 | ... BE45: =IF($X$12="Cost Savings",BE36,0) -> 0
B47: Financial Target | F47: =F41+F44 -> 10 | G47: =G41+G44 -> 10 | H47: =H41+H44 -> 10 | I47: =I41+I44 -> 10 | J47: =J41+J44 -> 10 | K47: =K41+K44 -> 10 | L47: =L41+L44 -> 10 | M47: =M41+M44 -> 10 | ... BE47: =BE41+BE44 -> 10
B48: Financial Actual | F48: =F42+F45 -> 0 | G48: =G42+G45 -> 0 | H48: =H42+H45 -> 0 | I48: =I42+I45 -> 0 | J48: =J42+J45 -> 0 | K48: =K42+K45 -> 0 | L48: =L42+L45 -> 0 | M48: =M42+M45 -> 0 | ... BE48: =BE42+BE45 -> 0
E49: To Date
...

Sheet P2
B3: PROJECT | F3: Claude Code Implementation | AG3: Strategic Value | AO3: =F8 -> Complex Tool | AV3: =IF(F7="",0,VLOOKUP(F7,Lookups!B4:H8,3)) -> 25 | AZ3: =NOW() -> 45961.687
AG4: Stage Multiplier (today) | AO4: =VLOOKUP(COUNTIF(AR10:AT21,"<="&AZ3),Table3357[],2) -> Dev | AV4: =IF(AO4="Not Def",0,VLOOKUP(AO4,Lookups!L4:M8,2)) -> 0.4 | AZ4: Current Qtr | BC4: =VLOOKUP((YEAR(AZ3)&"-"&MONTH(AZ3)),Lookups!S3:U21,2) -> 2025-Q4
B5: Description (Use Case) | F5: Claude Code solves the problem of slow, error-prone development cycles by automating coding and debugging, accelerating delivery timelines, reducing costs, and improving overall developer efficiency and output quality. | AG5: Stage Last Quarter | AO5: =VLOOKUP(COUNTIF(AR10:AT21,"<"&VLOOKUP(BC4,Lookups!W3:Y9,2)),Table3357[],2) -> Not Def | AQ5: =IF(AV5=1,"No Change","Progression") -> Progression | AV5: =IF(AO4="Not Def",0,IF(AO5=AO4,1,1.2)) -> 1.2
AG6: PROJECT SCORE | AV6: =AV3*AV4*AV5 -> 12
B7: Category | F7: L2. Sophisticated AI tooling for development/operations but generally limited to a single department or workflow | Y7: Ratio Impacted | AC7: R&D
B8: Strategic Value Level | F8: =IF(F7="","",VLOOKUP(F7,Lookups!B4:H8,2)) -> Complex Tool
B9: Examples | F9: =IF(F7="","",VLOOKUP(F7,Lookups!B4:H8,4)) -> AI-powered code review, automated testing, advanced development environments | AG9: Stage | AJ9: Tasks | AO9: Target | AR9: Completed | AU9: Days to Target | AY9: Notes
AG10: Idea | AJ10: Project Defined | AO10: 45931 | AR10: 45931 | AU10: =IF(AO10=$BK$3,"Missing Target",IF(AR10=$BK$3,IF($AZ$3>AO10,INT($AZ$3-AO10)&" Day(s) Overdue","Incomplete"),IF(AR10>AO10,INT(AR10-AO10)&" Day(s) Late",IF(AR10=AO10,"OK",INT(AO10-AR10)&" Day(s) Ahead")))) -> OK
B11: PROJECT RESOURCES | F11: KEY PERFORMANCE INDICATORS / MEASURES OF SUCCESS | AJ11: Business Case approved | AO11: 45936 | AR11: 45936 | AU11: =IF(AO11=$BK$3,"Missing Target",IF(AR11=$BK$3,IF($AZ$3>AO11,INT($AZ$3-AO11)&" Day(s) Overdue","Incomplete"),IF(AR11>AO11,INT(AR11-AO11)&" Day(s) Late",IF(AR11=AO11,"OK",INT(AO11-AR11)&" Day(s) Ahead")))) -> OK
B12: AI Tools & Services | F12: =IF(F7="","",VLOOKUP(F7,Lookups!B4:H8,5)) -> Integration Depth | O12: =IF(F7="","",VLOOKUP(F7,Lookups!B4:H8,6)) -> Process Improvement | X12: =IF(F7="","",VLOOKUP(F7,Lookups!B4:H8,7)) -> Skills Development | AJ12: Resources Allocated | AO12: 45936 | AR12: 45936 | AU12: =IF(AO12=$BK$3,"Missing Target",IF(AR12=$BK$3,IF($AZ$3>AO12,INT($AZ$3-AO12)&" Day(s) Overdue","Incomplete"),IF(AR12>AO12,INT(AR12-AO12)&" Day(s) Late",IF(AR12=AO12,"OK",INT(AO12-AR12)&" Day(s) Ahead")))) -> OK
B13: Claude Code | F13: KPI | G13: Employee AI Tool Adoption Rate | O13: KPI | P13: Time Savings / Resolution Time Reduction | X13: KPI | Y13: Employee Productivity Gains | AG13: Develop | AJ13: Technical PoC validated | AO13: 45936 | AR13: 45936 | AU13: =IF(AO13=$BK$3,"Missing Target",IF(AR13=$BK$3,IF($AZ$3>AO13,INT($AZ$3-AO13)&" Day(s) Overdue","Incomplete"),IF(AR13>AO13,INT(AR13-AO13)&" Day(s) Late",IF(AR13=AO13,"OK",INT(AO13-AR13)&" Day(s) Ahead")))) -> OK
F14: How does this Project support this KPI? | O14: How does this Project support this KPI? | X14: How does this Project support this KPI? | AJ14: Dev roadmap documented | AO14: 45943 | AR14: 45931 | AU14: =IF(AO14=$BK$3,"Missing Target",IF(AR14=$BK$3,IF($AZ$3>AO14,INT($AZ$3-AO14)&" Day(s) Overdue","Incomplete"),IF(AR14>AO14,INT(AR14-AO14)&" Day(s) Late",IF(AR14=AO14,"OK",INT(AO14-AR14)&" Day(s) Ahead")))) -> 12 Day(s) Ahead
F15: Embeds Claude Code into the engineering workflow to increase daily AI-assisted development and code acceleration. | O15: Reduces time spent on coding, debugging, and reviews by using Claude Code to accelerate development tasks. | X15: Improves developer efficiency and output quality through AI-assisted coding, leading to higher productivity per engineer. | AJ15: Coding started | AO15: 45946 | AR15: 45946 | AU15: =IF(AO15=$A$1,"Missing Target",IF(AR15=$A$1,IF($AZ$3>AO15,INT($AZ$3-AO15)&" Day(s) Overdue","Incomplete"),IF(AR15>AO15,INT(AR15-AO15)&" Day(s) Late",IF(AR15=AO15,"OK",INT(AO15-AR15)&" Day(s) Ahead")))) -> OK
AG16: Pilot | AJ16: Deployment to beta | AU16: =IF(AO16=$A$1,"Missing Target",IF(AR16=$A$1,IF($AZ$3>AO16,INT($AZ$3-AO16)&" Day(s) Overdue","Incomplete"),IF(AR16>AO16,INT(AR16-AO16)&" Day(s) Late",IF(AR16=AO16,"OK",INT(AO16-AR16)&" Day(s) Ahead")))) -> Missing Target
B17: Contact | C17: ed.leisman@pyxissoftware.com | AJ17: Initial metrics/feedback | AU17: =IF(AO17=$A$1,"Missing Target",IF(AR17=$A$1,IF($AZ$3>AO17,INT($AZ$3-AO17)&" Day(s) Overdue","Incomplete"),IF(AR17>AO17,INT(AR17-AO17)&" Day(s) Late",IF(AR17=AO17,"OK",INT(AO17-AR17)&" Day(s) Ahead")))) -> Missing Target
B18: Prod Mgr | C18: Ed Leisman | F18: How will you measure the KPI? | O18: How will you measure the KPI? | X18: How will you measure the KPI? | AJ18: Feedback affecting code | AU18: =IF(AO18=$A$1,"Missing Target",IF(AR18=$A$1,IF($AZ$3>AO18,INT($AZ$3-AO18)&" Day(s) Overdue","Incomplete"),IF(AR18>AO18,INT(AR18-AO18)&" Day(s) Late",IF(AR18=AO18,"OK",INT(AO18-AR18)&" Day(s) Ahead")))) -> Missing Target
B19: Analyst | C19: Ed Leisman | F19: % of R&D team actively using Claude Code weekly. Target: ≥75% weekly active use within 90 days. | O19: Average time saved per task vs. baseline. Target: ≥30% reduction in time to complete common dev tasks within 6 months. | X19: Increase in completed story points or tasks per developer. Target: 15–25% gain in output within 6 months. | AG19: Live | AJ19: General release available | AU19: =IF(AO19=$A$1,"Missing Target",IF(AR19=$A$1,IF($AZ$3>AO19,INT($AZ$3-AO19)&" Day(s) Overdue","Incomplete"),IF(AR19>AO19,INT(AR19-AO19)&" Day(s) Late",IF(AR19=AO19,"OK",INT(AO19-AR19)&" Day(s) Ahead")))) -> Missing Target
B20: Tech Lead | C20: Ed Leisman | AJ20: Success metrics tracking | AU20: =IF(AO20=$A$1,"Missing Target",IF(AR20=$A$1,IF($AZ$3>AO20,INT($AZ$3-AO20)&" Day(s) Overdue","Incomplete"),IF(AR20>AO20,INT(AR20-AO20)&" Day(s) Late",IF(AR20=AO20,"OK",INT(AO20-AR20)&" Day(s) Ahead")))) -> Missing Target
B21: Exec | C21: Jason Stroud | AJ21: Feedback loop continuing | AU21: =IF(AO21=$A$1,"Missing Target",IF(AR21=$A$1,IF($AZ$3>AO21,INT($AZ$3-AO21)&" Day(s) Overdue","Incomplete"),IF(AR21>AO21,INT(AR21-AO21)&" Day(s) Late",IF(AR21=AO21,"OK",INT(AO21-AR21)&" Day(s) Ahead")))) -> Missing Target
B23: WEEKLY KPI TRACKER | F23: 1 | G23: =F23+1 -> 2 | H23: =G23+1 -> 3 | I23: =H23+1 -> 4 | J23: =I23+1 -> 5 | K23: =J23+1 -> 6 | L23: =K23+1 -> 7 | M23: =L23+1 -> 8 | N23: =M23+1 -> 9 | ... BE23: =BD23+1 -> 52
B24: Week Ending | F24: 45931 | G24: =F24+7 -> 45938 | H24: =G24+7 -> 45945 | I24: =H24+7 -> 45952 | J24: =I24+7 -> 45959 | K24: =J24+7 -> 45966 | L24: =K24+7 -> 45973 | M24: =L24+7 -> 45980 | N24: =M24+7 -> 45987 | ... BE24: =BD24+7 -> 46288
B25: =G13&" TARGET" -> Employee AI Tool Adoption Rate TARGET | F25: 0 | G25: =F25 -> 0 | H25: =G25 -> 0 | I25: =H25 -> 0 | J25: =I25 -> 0 | K25: =J25 -> 0 | L25: =K25 -> 0 | M25: =L25 -> 0 | N25: =M25 -> 0 | ... BE25: =BD25 -> 0
B26: Actual | F26: 0 | G26: 0 | H26: 0 | I26: 0 | J26: 0
B27: Delta | F27: =F26-F25 -> 0 | G27: =G26-G25 -> 0 | H27: =H26-H25 -> 0 | I27: =I26-I25 -> 0 | J27: =J26-J25 -> 0 | K27: =K26-K25 -> 0 | L27: =L26-L25 -> 0 | M27: =M26-M25 -> 0 | ... BE27: =BE26-BE25 -> 0
B28: Notes on this KPI (anything to add this week?)
B30: =P13&" TARGET" -> Time Savings / Resolution Time Reduction TARGET | F30: 0 | G30: =F30 -> 0 | H30: =G30 -> 0 | I30: =H30 -> 0 | J30: =I30 -> 0 | K30: =J30 -> 0 | L30: =K30 -> 0 | M30: =L30 -> 0 | N30: =M30 -> 0 | ... BE30: =BD30 -> 0
B31: Actual | F31: 0 | G31: 0 | H31: 0 | I31: 0 | J31: 0
B32: Delta | F32: =F31-F30 -> 0 | G32: =G31-G30 -> 0 | H32: =H31-H30 -> 0 | I32: =I31-I30 -> 0 | J32: =J31-J30 -> 0 | K32: =K31-K30 -> 0 | L32: =L31-L30 -> 0 | M32: =M31-M30 -> 0 | ... BE32: =BE31-BE30 -> 0
B33: Notes on this KPI (anything to add this week?)
B35: =Y13&" TARGET" -> Employee Productivity Gains TARGET | F35: 0 | G35: =F35 -> 0 | H35: =G35 -> 0 | I35: =H35 -> 0 | J35: =I35 -> 0 | K35: =J35 -> 0 | L35: =K35 -> 0 | M35: =L35 -> 0 | N35: =M35 -> 0 | ... BE35: =BD35 -> 0
B36: Actual | F36: 0 | G36: 0 | H36: 0 | I36: 0 | J36: 0
B37: Delta | F37: =F36-F35 -> 0 | G37: =G36-G35 -> 0 | H37: =H36-H35 -> 0 | I37: =I36-I35 -> 0 | J37: =J36-J35 -> 0 | K37: =K36-K35 -> 0 | L37: =L36-L35 -> 0 | M37: =M36-M35 -> 0 | ... BE37: =BE36-BE35 -> 0
B38: Notes on this KPI (anything to add this week?)
B41: Revenue Target | F41: =IF($X$12="Revenue Impact",F35,0) -> 0 | G41: =IF($X$12="Revenue Impact",G35,0) -> 0 | H41: =IF($X$12="Revenue Impact",H35,0) -> 0 | I41: =IF($X$12="Revenue Impact",I35,0) -> 0 | J41: =IF($X$12="Revenue Impact",J35,0) -> 0 | K41: =IF($X$12="Revenue Impact",K35,0) -> 0 | L41: =IF($X$12="Revenue Impact",L35,0) -> 0 | M41: =IF($X$12="Revenue Impact",M35,0) -> 0 | ... BE41: =IF($X$12="Revenue Impact",BE35,0) -> 0
B42: Revenue Actual | F42: =IF($X$12="Revenue Impact",F36,0) -> 0 | G42: =IF($X$12="Revenue Impact",G36,0) -> 0 | H42: =IF($X$12="Revenue Impact",H36,0) -> 0 | I42: =IF($X$12="Revenue Impact",I36,0) -> 0 | J42: =IF($X$12="Revenue Impact",J36,0) -> 0 | K42: =IF($X$12="Revenue Impact",K36,0) -> 0 | L42: =IF($X$12="Revenue Impact",L36,0) -> 0 | M42: =IF($X$12="Revenue Impact",M36,0) -> 0 | ... BE42: =IF($X$12="Revenue Impact",BE36,0) -> 0
B44: Cost Target | F44: =IF($X$12="Cost Savings",F35,0) -> 0 | G44: =IF($X$12="Cost Savings",G35,0) -> 0 | H44: =IF($X$12="Cost Savings",H35,0) -> 0 | I44: =IF($X$12="Cost Savings",I35,0) -> 0 | J44: =IF($X$12="Cost Savings",J35,0) -> 0 | K44: =IF($X$12="Cost Savings",K35,0) -> 0 | L44: =IF($X$12="Cost Savings",L35,0) -> 0 | M44: =IF($X$12="Cost Savings",M35,0) -> 0 | ... BE44: =IF($X$12="Cost Savings",BE35,0) -> 0
B45: Cost Actual | F45: =IF($X$12="Cost Savings",F36,0) -> 0 | G45: =IF($X$12="Cost Savings",G36,0) -> 0 | H45: =IF($X$12="Cost Savings",H36,0) -> 0 | I45: =IF($X$12="Cost Savings",I36,0) -> 0 | J45: =IF($X$12="Cost Savings",J36,0) -> 0 | K45: =IF($X$12="Cost Savings",K36,0) -> 0 | L45: =IF($X$12="Cost Savings",L36,0) -> 0 | M45: =IF($X$12="Cost Savings",M36,0) -> 0 | ... BE45: =IF($X$12="Cost Savings",BE36,0) -> 0
B47: Financial Target | F47: =F41+F44 -> 0 | G47: =G41+G44 -> 0 | H47: =H41+H44 -> 0 | I47: =I41+I44 -> 0 | J47: =J41+J44 -> 0 | K47: =K41+K44 -> 0 | L47: =L41+L44 -> 0 | M47: =M41+M44 -> 0 | ... BE47: =BE41+BE44 -> 0
B48: Financial Actual | F48: =F42+F45 -> 0 | G48: =G42+G45 -> 0 | H48: =H42+H45 -> 0 | I48: =I42+I45 -> 0 | J48: =J42+J45 -> 0 | K48: =K42+K45 -> 0 | L48: =L42+L45 -> 0 | M48: =M42+M45 -> 0 | ... BE48: =BE42+BE45 -> 0
E49: To Date
...

Sheet P3
B3: PROJECT | AG3: Strategic Value | AO3: =F8 | AV3: =IF(F7="",0,VLOOKUP(F7,Lookups!B4:H8,3)) -> 0 | AZ3: =NOW() -> 45961.687
AG4: Stage Multiplier (today) | AO4: =VLOOKUP(COUNTIF(AR10:AT21,"<="&AZ3),Table3357[],2) -> Not Def | AV4: =IF(AO4="Not Def",0,VLOOKUP(AO4,Lookups!L4:M8,2)) -> 0 | AZ4: Current Qtr | BC4: =VLOOKUP((YEAR(AZ3)&"-"&MONTH(AZ3)),Lookups!S3:U21,2) -> 2025-Q4
B5: Description (Use Case) | AG5: Stage Last Quarter | AO5: =VLOOKUP(COUNTIF(AR10:AT21,"<"&VLOOKUP(BC4,Lookups!W3:Y9,2)),Table3357[],2) -> Not Def | AQ5: =IF(AV5=1,"No Change","Progression") -> Progression | AV5: =IF(AO4="Not Def",0,IF(AO5=AO4,1,1.2)) -> 0
AG6: PROJECT SCORE | AV6: =AV3*AV4*AV5 -> 0
B7: Category | Y7: Ratio Impacted
B8: Strategic Value Level | F8: =IF(F7="","",VLOOKUP(F7,Lookups!B4:H8,2))
B9: Examples | F9: =IF(F7="","",VLOOKUP(F7,Lookups!B4:H8,4)) | AG9: Stage | AJ9: Tasks | AO9: Target | AR9: Completed | AU9: Days to Target | AY9: Notes
AG10: Idea | AJ10: Project Defined | AU10: =IF(AO10=$BK$3,"Missing Target",IF(AR10=$BK$3,IF($AZ$3>AO10,INT($AZ$3-AO10)&" Day(s) Overdue","Incomplete"),IF(AR10>AO10,INT(AR10-AO10)&" Day(s) Late",IF(AR10=AO10,"OK",INT(AO10-AR10)&" Day(s) Ahead")))) -> Missing Target
B11: PROJECT RESOURCES | F11: KEY PERFORMANCE INDICATORS / MEASURES OF SUCCESS | AJ11: Business Case approved | AU11: =IF(AO11=$BK$3,"Missing Target",IF(AR11=$BK$3,IF($AZ$3>AO11,INT($AZ$3-AO11)&" Day(s) Overdue","Incomplete"),IF(AR11>AO11,INT(AR11-AO11)&" Day(s) Late",IF(AR11=AO11,"OK",INT(AO11-AR11)&" Day(s) Ahead")))) -> Missing Target
B12: AI Tools & Services | F12: =IF(F7="","",VLOOKUP(F7,Lookups!B4:H8,5)) | O12: =IF(F7="","",VLOOKUP(F7,Lookups!B4:H8,6)) | X12: =IF(F7="","",VLOOKUP(F7,Lookups!B4:H8,7)) | AJ12: Resources Allocated | AU12: =IF(AO12=$BK$3,"Missing Target",IF(AR12=$BK$3,IF($AZ$3>AO12,INT($AZ$3-AO12)&" Day(s) Overdue","Incomplete"),IF(AR12>AO12,INT(AR12-AO12)&" Day(s) Late",IF(AR12=AO12,"OK",INT(AO12-AR12)&" Day(s) Ahead")))) -> Missing Target
F13: KPI | O13: KPI | X13: KPI | AG13: Develop | AJ13: Technical PoC validated | AU13: =IF(AO13=$BK$3,"Missing Target",IF(AR13=$BK$3,IF($AZ$3>AO13,INT($AZ$3-AO13)&" Day(s) Overdue","Incomplete"),IF(AR13>AO13,INT(AR13-AO13)&" Day(s) Late",IF(AR13=AO13,"OK",INT(AO13-AR13)&" Day(s) Ahead")))) -> Missing Target
F14: How does this Project support this KPI? | O14: How does this Project support this KPI? | X14: How does this Project support this KPI? | AJ14: Dev roadmap documented | AU14: =IF(AO14=$BK$3,"Missing Target",IF(AR14=$BK$3,IF($AZ$3>AO14,INT($AZ$3-AO14)&" Day(s) Overdue","Incomplete"),IF(AR14>AO14,INT(AR14-AO14)&" Day(s) Late",IF(AR14=AO14,"OK",INT(AO14-AR14)&" Day(s) Ahead")))) -> Missing Target
AJ15: Coding started | AU15: =IF(AO15=$A$1,"Missing Target",IF(AR15=$A$1,IF($AZ$3>AO15,INT($AZ$3-AO15)&" Day(s) Overdue","Incomplete"),IF(AR15>AO15,INT(AR15-AO15)&" Day(s) Late",IF(AR15=AO15,"OK",INT(AO15-AR15)&" Day(s) Ahead")))) -> Missing Target
AG16: Pilot | AJ16: Deployment to beta | AU16: =IF(AO16=$A$1,"Missing Target",IF(AR16=$A$1,IF($AZ$3>AO16,INT($AZ$3-AO16)&" Day(s) Overdue","Incomplete"),IF(AR16>AO16,INT(AR16-AO16)&" Day(s) Late",IF(AR16=AO16,"OK",INT(AO16-AR16)&" Day(s) Ahead")))) -> Missing Target
B17: Contact | AJ17: Initial metrics/feedback | AU17: =IF(AO17=$A$1,"Missing Target",IF(AR17=$A$1,IF($AZ$3>AO17,INT($AZ$3-AO17)&" Day(s) Overdue","Incomplete"),IF(AR17>AO17,INT(AR17-AO17)&" Day(s) Late",IF(AR17=AO17,"OK",INT(AO17-AR17)&" Day(s) Ahead")))) -> Missing Target
B18: Prod Mgr | F18: How will you measure the KPI? | O18: How will you measure the KPI? | X18: How will you measure the KPI? | AJ18: Feedback affecting code | AU18: =IF(AO18=$A$1,"Missing Target",IF(AR18=$A$1,IF($AZ$3>AO18,INT($AZ$3-AO18)&" Day(s) Overdue","Incomplete"),IF(AR18>AO18,INT(AR18-AO18)&" Day(s) Late",IF(AR18=AO18,"OK",INT(AO18-AR18)&" Day(s) Ahead")))) -> Missing Target
B19: Analyst | AG19: Live | AJ19: General release available | AU19: =IF(AO19=$A$1,"Missing Target",IF(AR19=$A$1,IF($AZ$3>AO19,INT($AZ$3-AO19)&" Day(s) Overdue","Incomplete"),IF(AR19>AO19,INT(AR19-AO19)&" Day(s) Late",IF(AR19=AO19,"OK",INT(AO19-AR19)&" Day(s) Ahead")))) -> Missing Target
B20: Tech Lead | AJ20: Success metrics tracking | AU20: =IF(AO20=$A$1,"Missing Target",IF(AR20=$A$1,IF($AZ$3>AO20,INT($AZ$3-AO20)&" Day(s) Overdue","Incomplete"),IF(AR20>AO20,INT(AR20-AO20)&" Day(s) Late",IF(AR20=AO20,"OK",INT(AO20-AR20)&" Day(s) Ahead")))) -> Missing Target
B21: Exec | AJ21: Feedback loop continuing | AU21: =IF(AO21=$A$1,"Missing Target",IF(AR21=$A$1,IF($AZ$3>AO21,INT($AZ$3-AO21)&" Day(s) Overdue","Incomplete"),IF(AR21>AO21,INT(AR21-AO21)&" Day(s) Late",IF(AR21=AO21,"OK",INT(AO21-AR21)&" Day(s) Ahead")))) -> Missing Target
B23: WEEKLY KPI TRACKER | F23: 1 | G23: =F23+1 -> 2 | H23: =G23+1 -> 3 | I23: =H23+1 -> 4 | J23: =I23+1 -> 5 | K23: =J23+1 -> 6 | L23: =K23+1 -> 7 | M23: =L23+1 -> 8 | N23: =M23+1 -> 9 | ... BE23: =BD23+1 -> 52
B24: Week Ending | F24: =NOW() -> 45961.687 | G24: =F24+7 -> 45968.687 | H24: =G24+7 -> 45975.687 | I24: =H24+7 -> 45982.687 | J24: =I24+7 -> 45989.687 | K24: =J24+7 -> 45996.687 | L24: =K24+7 -> 46003.687 | M24: =L24+7 -> 46010.687 | N24: =M24+7 -> 46017.687 | ... BE24: =BD24+7 -> 46318.687
B25: =G13&" TARGET" -> TARGET | G25: =F25 -> 0 | H25: =G25 -> 0 | I25: =H25 -> 0 | J25: =I25 -> 0 | K25: =J25 -> 0 | L25: =K25 -> 0 | M25: =L25 -> 0 | N25: 60 | O25: 60 | P25: 65 | Q25: 65 | R25: 66 | S25: 67 | T25: 68 | U25: 69 | V25: 70 | W25: 71 | X25: 72 | Y25: 73 | Z25: 74 | AA25: 75 | AB25: 76 | AC25: 77 | AD25: 78 | AE25: 79 | AF25: 80 | AG25: 80 | AH25: 80 | AI25: 80 | AJ25: 80 | AK25: 80 | AL25: 80 | AM25: 80 | AN25: 80 | AO25: 80 | AP25: 80 | AQ25: 80 | AR25: 80 | AS25: 80 | AT25: 80 | AU25: 80 | AV25: 80 | AW25: 80 | AX25: 80 | AY25: 80 | AZ25: 80 | BA25: 80 | BB25: 80 | BC25: 80 | BD25: 80 | BE25: 80
B26: Actual
B27: Delta | F27: =F26-F25 -> 0 | G27: =G26-G25 -> 0 | H27: =H26-H25 -> 0 | I27: =I26-I25 -> 0 | J27: =J26-J25 -> 0 | K27: =K26-K25 -> 0 | L27: =L26-L25 -> 0 | M27: =M26-M25 -> 0 | ... BE27: =BE26-BE25 -> -80
B28: Notes on this KPI (anything to add this week?)
B30: =P13&" TARGET" -> TARGET | G30: =F30 -> 0 | H30: =G30 -> 0 | I30: =H30 -> 0 | J30: =I30 -> 0 | K30: =J30 -> 0 | L30: =K30 -> 0 | M30: =L30 -> 0 | N30: =M30 -> 0 | ... BE30: =BD30 -> 0
B31: Actual
B32: Delta | F32: =F31-F30 -> 0 | G32: =G31-G30 -> 0 | H32: =H31-H30 -> 0 | I32: =I31-I30 -> 0 | J32: =J31-J30 -> 0 | K32: =K31-K30 -> 0 | L32: =L31-L30 -> 0 | M32: =M31-M30 -> 0 | ... BE32: =BE31-BE30 -> 0
B33: Notes on this KPI (anything to add this week?)
B35: =Y13&" TARGET" -> TARGET | G35: =F35 -> 0 | H35: =G35 -> 0 | I35: =H35 -> 0 | J35: =I35 -> 0 | K35: =J35 -> 0 | L35: =K35 -> 0 | M35: =L35 -> 0 | N35: =M35 -> 0 | ... BE35: =BD35 -> 0
B36: Actual | F36: 0 | G36: 0 | H36: 0 | I36: 0 | J36: 0 | K36: 0 | L36: 0 | M36: 0
B37: Delta | F37: =F36-F35 -> 0 | G37: =G36-G35 -> 0 | H37: =H36-H35 -> 0 | I37: =I36-I35 -> 0 | J37: =J36-J35 -> 0 | K37: =K36-K35 -> 0 | L37: =L36-L35 -> 0 | M37: =M36-M35 -> 0 | ... BE37: =BE36-BE35 -> 0
B38: Notes on this KPI (anything to add this week?)
B41: Revenue Target | F41: =IF($X$12="Revenue Impact",F35,0) -> 0 | G41: =IF($X$12="Revenue Impact",G35,0) -> 0 | H41: =IF($X$12="Revenue Impact",H35,0) -> 0 | I41: =IF($X$12="Revenue Impact",I35,0) -> 0 | J41: =IF($X$12="Revenue Impact",J35,0) -> 0 | K41: =IF($X$12="Revenue Impact",K35,0) -> 0 | L41: =IF($X$12="Revenue Impact",L35,0) -> 0 | M41: =IF($X$12="Revenue Impact",M35,0) -> 0 | ... BE41: =IF($X$12="Revenue Impact",BE35,0) -> 0
B42: Revenue Actual | F42: =IF($X$12="Revenue Impact",F36,0) -> 0 | G42: =IF($X$12="Revenue Impact",G36,0) -> 0 | H42: =IF($X$12="Revenue Impact",H36,0) -> 0 | I42: =IF($X$12="Revenue Impact",I36,0) -> 0 | J42: =IF($X$12="Revenue Impact",J36,0) -> 0 | K42: =IF($X$12="Revenue Impact",K36,0) -> 0 | L42: =IF($X$12="Revenue Impact",L36,0) -> 0 | M42: =IF($X$12="Revenue Impact",M36,0) -> 0 | ... BE42: =IF($X$12="Revenue Impact",BE36,0) -> 0
B44: Cost Target | F44: =IF($X$12="Cost Savings",F35,0) -> 0 | G44: =IF($X$12="Cost Savings",G35,0) -> 0 | H44: =IF($X$12="Cost Savings",H35,0) -> 0 | I44: =IF($X$12="Cost Savings",I35,0) -> 0 | J44: =IF($X$12="Cost Savings",J35,0) -> 0 | K44: =IF($X$12="Cost Savings",K35,0) -> 0 | L44: =IF($X$12="Cost Savings",L35,0) -> 0 | M44: =IF($X$12="Cost Savings",M35,0) -> 0 | ... BE44: =IF($X$12="Cost Savings",BE35,0) -> 0
B45: Cost Actual | F45: =IF($X$12="Cost Savings",F36,0) -> 0 | G45: =IF($X$12="Cost Savings",G36,0) -> 0 | H45: =IF($X$12="Cost Savings",H36,0) -> 0 | I45: =IF($X$12="Cost Savings",I36,0) -> 0 | J45: =IF($X$12="Cost Savings",J36,0) -> 0 | K45: =IF($X$12="Cost Savings",K36,0) -> 0 | L45: =IF($X$12="Cost Savings",L36,0) -> 0 | M45: =IF($X$12="Cost Savings",M36,0) -> 0 | ... BE45: =IF($X$12="Cost Savings",BE36,0) -> 0
B47: Financial Target | F47: =F41+F44 -> 0 | G47: =G41+G44 -> 0 | H47: =H41+H44 -> 0 | I47: =I41+I44 -> 0 | J47: =J41+J44 -> 0 | K47: =K41+K44 -> 0 | L47: =L41+L44 -> 0 | M47: =M41+M44 -> 0 | ... BE47: =BE41+BE44 -> 0
B48: Financial Actual | F48: =F42+F45 -> 0 | G48: =G42+G45 -> 0 | H48: =H42+H45 -> 0 | I48: =I42+I45 -> 0 | J48: =J42+J45 -> 0 | K48: =K42+K45 -> 0 | L48: =L42+L45 -> 0 | M48: =M42+M45 -> 0 | ... BE48: =BE42+BE45 -> 0
E49: To Date
...

Sheet P4
B3: PROJECT | AG3: Strategic Value | AO3: =F8 | AV3: =IF(F7="",0,VLOOKUP(F7,Lookups!B4:H8,3)) -> 0 | AZ3: =NOW() -> 45961.687
AG4: Stage Multiplier (today) | AO4: =VLOOKUP(COUNTIF(AR10:AT21,"<="&AZ3),Table3357[],2) -> Not Def | AV4: =IF(AO4="Not Def",0,VLOOKUP(AO4,Lookups!L4:M8,2)) -> 0 | AZ4: Current Qtr | BC4: =VLOOKUP((YEAR(AZ3)&"-"&MONTH(AZ3)),Lookups!S3:U21,2) -> 2025-Q4
B5: Description (Use Case) | AG5: Stage Last Quarter | AO5: =VLOOKUP(COUNTIF(AR10:AT21,"<"&VLOOKUP(BC4,Lookups!W3:Y9,2)),Table3357[],2) -> Not Def | AQ5: =IF(AV5=1,"No Change","Progression") -> Progression | AV5: =IF(AO4="Not Def",0,IF(AO5=AO4,1,1.2)) -> 0
AG6: PROJECT SCORE | AV6: =AV3*AV4*AV5 -> 0
B7: Category | Y7: Ratio Impacted
B8: Strategic Value Level | F8: =IF(F7="","",VLOOKUP(F7,Lookups!B4:H8,2))
B9: Examples | F9: =IF(F7="","",VLOOKUP(F7,Lookups!B4:H8,4)) | AG9: Stage | AJ9: Tasks | AO9: Target | AR9: Completed | AU9: Days to Target | AY9: Notes
AG10: Idea | AJ10: Project Defined | AU10: =IF(AO10=$BK$3,"Missing Target",IF(AR10=$BK$3,IF($AZ$3>AO10,INT($AZ$3-AO10)&" Day(s) Overdue","Incomplete"),IF(AR10>AO10,INT(AR10-AO10)&" Day(s) Late",IF(AR10=AO10,"OK",INT(AO10-AR10)&" Day(s) Ahead")))) -> Missing Target
B11: PROJECT RESOURCES | F11: KEY PERFORMANCE INDICATORS / MEASURES OF SUCCESS | AJ11: Business Case approved | AU11: =IF(AO11=$BK$3,"Missing Target",IF(AR11=$BK$3,IF($AZ$3>AO11,INT($AZ$3-AO11)&" Day(s) Overdue","Incomplete"),IF(AR11>AO11,INT(AR11-AO11)&" Day(s) Late",IF(AR11=AO11,"OK",INT(AO11-AR11)&" Day(s) Ahead")))) -> Missing Target
B12: AI Tools & Services | F12: =IF(F7="","",VLOOKUP(F7,Lookups!B4:H8,5)) | O12: =IF(F7="","",VLOOKUP(F7,Lookups!B4:H8,6)) | X12: =IF(F7="","",VLOOKUP(F7,Lookups!B4:H8,7)) | AJ12: Resources Allocated | AU12: =IF(AO12=$BK$3,"Missing Target",IF(AR12=$BK$3,IF($AZ$3>AO12,INT($AZ$3-AO12)&" Day(s) Overdue","Incomplete"),IF(AR12>AO12,INT(AR12-AO12)&" Day(s) Late",IF(AR12=AO12,"OK",INT(AO12-AR12)&" Day(s) Ahead")))) -> Missing Target
F13: KPI | O13: KPI | X13: KPI | AG13: Develop | AJ13: Technical PoC validated | AU13: =IF(AO13=$BK$3,"Missing Target",IF(AR13=$BK$3,IF($AZ$3>AO13,INT($AZ$3-AO13)&" Day(s) Overdue","Incomplete"),IF(AR13>AO13,INT(AR13-AO13)&" Day(s) Late",IF(AR13=AO13,"OK",INT(AO13-AR13)&" Day(s) Ahead")))) -> Missing Target
F14: How does this Project support this KPI? | O14: How does this Project support this KPI? | X14: How does this Project support this KPI? | AJ14: Dev roadmap documented | AU14: =IF(AO14=$BK$3,"Missing Target",IF(AR14=$BK$3,IF($AZ$3>AO14,INT($AZ$3-AO14)&" Day(s) Overdue","Incomplete"),IF(AR14>AO14,INT(AR14-AO14)&" Day(s) Late",IF(AR14=AO14,"OK",INT(AO14-AR14)&" Day(s) Ahead")))) -> Missing Target
AJ15: Coding started | AU15: =IF(AO15=$A$1,"Missing Target",IF(AR15=$A$1,IF($AZ$3>AO15,INT($AZ$3-AO15)&" Day(s) Overdue","Incomplete"),IF(AR15>AO15,INT(AR15-AO15)&" Day(s) Late",IF(AR15=AO15,"OK",INT(AO15-AR15)&" Day(s) Ahead")))) -> Missing Target
AG16: Pilot | AJ16: Deployment to beta | AU16: =IF(AO16=$A$1,"Missing Target",IF(AR16=$A$1,IF($AZ$3>AO16,INT($AZ$3-AO16)&" Day(s) Overdue","Incomplete"),IF(AR16>AO16,INT(AR16-AO16)&" Day(s) Late",IF(AR16=AO16,"OK",INT(AO16-AR16)&" Day(s) Ahead")))) -> Missing Target
B17: Contact | AJ17: Initial metrics/feedback | AU17: =IF(AO17=$A$1,"Missing Target",IF(AR17=$A$1,IF($AZ$3>AO17,INT($AZ$3-AO17)&" Day(s) Overdue","Incomplete"),IF(AR17>AO17,INT(AR17-AO17)&" Day(s) Late",IF(AR17=AO17,"OK",INT(AO17-AR17)&" Day(s) Ahead")))) -> Missing Target
B18: Prod Mgr | F18: How will you measure the KPI? | O18: How will you measure the KPI? | X18: How will you measure the KPI? | AJ18: Feedback affecting code | AU18: =IF(AO18=$A$1,"Missing Target",IF(AR18=$A$1,IF($AZ$3>AO18,INT($AZ$3-AO18)&" Day(s) Overdue","Incomplete"),IF(AR18>AO18,INT(AR18-AO18)&" Day(s) Late",IF(AR18=AO18,"OK",INT(AO18-AR18)&" Day(s) Ahead")))) -> Missing Target
B19: Analyst | AG19: Live | AJ19: General release available | AU19: =IF(AO19=$A$1,"Missing Target",IF(AR19=$A$1,IF($AZ$3>AO19,INT($AZ$3-AO19)&" Day(s) Overdue","Incomplete"),IF(AR19>AO19,INT(AR19-AO19)&" Day(s) Late",IF(AR19=AO19,"OK",INT(AO19-AR19)&" Day(s) Ahead")))) -> Missing Target
B20: Tech Lead | AJ20: Success metrics tracking | AU20: =IF(AO20=$A$1,"Missing Target",IF(AR20=$A$1,IF($AZ$3>AO20,INT($AZ$3-AO20)&" Day(s) Overdue","Incomplete"),IF(AR20>AO20,INT(AR20-AO20)&" Day(s) Late",IF(AR20=AO20,"OK",INT(AO20-AR20)&" Day(s) Ahead")))) -> Missing Target
B21: Exec | AJ21: Feedback loop continuing | AU21: =IF(AO21=$A$1,"Missing Target",IF(AR21=$A$1,IF($AZ$3>AO21,INT($AZ$3-AO21)&" Day(s) Overdue","Incomplete"),IF(AR21>AO21,INT(AR21-AO21)&" Day(s) Late",IF(AR21=AO21,"OK",INT(AO21-AR21)&" Day(s) Ahead")))) -> Missing Target
B23: WEEKLY KPI TRACKER | F23: 1 | G23: =F23+1 -> 2 | H23: =G23+1 -> 3 | I23: =H23+1 -> 4 | J23: =I23+1 -> 5 | K23: =J23+1 -> 6 | L23: =K23+1 -> 7 | M23: =L23+1 -> 8 | N23: =M23+1 -> 9 | ... BE23: =BD23+1 -> 52
B24: Week Ending | F24: =NOW() -> 45961.687 | G24: =F24+7 -> 45968.687 | H24: =G24+7 -> 45975.687 | I24: =H24+7 -> 45982.687 | J24: =I24+7 -> 45989.687 | K24: =J24+7 -> 45996.687 | L24: =K24+7 -> 46003.687 | M24: =L24+7 -> 46010.687 | N24: =M24+7 -> 46017.687 | ... BE24: =BD24+7 -> 46318.687
B25: =G13&" TARGET" -> TARGET | G25: =F25 -> 0 | H25: =G25 -> 0 | I25: =H25 -> 0 | J25: =I25 -> 0 | K25: =J25 -> 0 | L25: =K25 -> 0 | M25: =L25 -> 0 | N25: 60 | O25: 60 | P25: 65 | Q25: 65 | R25: 66 | S25: 67 | T25: 68 | U25: 69 | V25: 70 | W25: 71 | X25: 72 | Y25: 73 | Z25: 74 | AA25: 75 | AB25: 76 | AC25: 77 | AD25: 78 | AE25: 79 | AF25: 80 | AG25: 80 | AH25: 80 | AI25: 80 | AJ25: 80 | AK25: 80 | AL25: 80 | AM25: 80 | AN25: 80 | AO25: 80 | AP25: 80 | AQ25: 80 | AR25: 80 | AS25: 80 | AT25: 80 | AU25: 80 | AV25: 80 | AW25: 80 | AX25: 80 | AY25: 80 | AZ25: 80 | BA25: 80 | BB25: 80 | BC25: 80 | BD25: 80 | BE25: 80
B26: Actual
B27: Delta | F27: =F26-F25 -> 0 | G27: =G26-G25 -> 0 | H27: =H26-H25 -> 0 | I27: =I26-I25 -> 0 | J27: =J26-J25 -> 0 | K27: =K26-K25 -> 0 | L27: =L26-L25 -> 0 | M27: =M26-M25 -> 0 | ... BE27: =BE26-BE25 -> -80
B28: Notes on this KPI (anything to add this week?)
B30: =P13&" TARGET" -> TARGET | G30: =F30 -> 0 | H30: =G30 -> 0 | I30: =H30 -> 0 | J30: =I30 -> 0 | K30: =J30 -> 0 | L30: =K30 -> 0 | M30: =L30 -> 0 | N30: =M30 -> 0 | ... BE30: =BD30 -> 0
B31: Actual
B32: Delta | F32: =F31-F30 -> 0 | G32: =G31-G30 -> 0 | H32: =H31-H30 -> 0 | I32: =I31-I30 -> 0 | J32: =J31-J30 -> 0 | K32: =K31-K30 -> 0 | L32: =L31-L30 -> 0 | M32: =M31-M30 -> 0 | ... BE32: =BE31-BE30 -> 0
B33: Notes on this KPI (anything to add this week?)
B35: =Y13&" TARGET" -> TARGET | G35: =F35 -> 0 | H35: =G35 -> 0 | I35: =H35 -> 0 | J35: =I35 -> 0 | K35: =J35 -> 0 | L35: =K35 -> 0 | M35: =L35 -> 0 | N35: =M35 -> 0 | ... BE35: =BD35 -> 0
B36: Actual | F36: 0 | G36: 0 | H36: 0 | I36: 0 | J36: 0 | K36: 0 | L36: 0 | M36: 0
B37: Delta | F37: =F36-F35 -> 0 | G37: =G36-G35 -> 0 | H37: =H36-H35 -> 0 | I37: =I36-I35 -> 0 | J37: =J36-J35 -> 0 | K37: =K36-K35 -> 0 | L37: =L36-L35 -> 0 | M37: =M36-M35 -> 0 | ... BE37: =BE36-BE35 -> 0
B38: Notes on this KPI (anything to add this week?)
B41: Revenue Target | F41: =IF($X$12="Revenue Impact",F35,0) -> 0 | G41: =IF($X$12="Revenue Impact",G35,0) -> 0 | H41: =IF($X$12="Revenue Impact",H35,0) -> 0 | I41: =IF($X$12="Revenue Impact",I35,0) -> 0 | J41: =IF($X$12="Revenue Impact",J35,0) -> 0 | K41: =IF($X$12="Revenue Impact",K35,0) -> 0 | L41: =IF($X$12="Revenue Impact",L35,0) -> 0 | M41: =IF($X$12="Revenue Impact",M35,0) -> 0 | ... BE41: =IF($X$12="Revenue Impact",BE35,0) -> 0
B42: Revenue Actual | F42: =IF($X$12="Revenue Impact",F36,0) -> 0 | G42: =IF($X$12="Revenue Impact",G36,0) -> 0 | H42: =IF($X$12="Revenue Impact",H36,0) -> 0 | I42: =IF($X$12="Revenue Impact",I36,0) -> 0 | J42: =IF($X$12="Revenue Impact",J36,0) -> 0 | K42: =IF($X$12="Revenue Impact",K36,0) -> 0 | L42: =IF($X$12="Revenue Impact",L36,0) -> 0 | M42: =IF($X$12="Revenue Impact",M36,0) -> 0 | ... BE42: =IF($X$12="Revenue Impact",BE36,0) -> 0
B44: Cost Target | F44: =IF($X$12="Cost Savings",F35,0) -> 0 | G44: =IF($X$12="Cost Savings",G35,0) -> 0 | H44: =IF($X$12="Cost Savings",H35,0) -> 0 | I44: =IF($X$12="Cost Savings",I35,0) -> 0 | J44: =IF($X$12="Cost Savings",J35,0) -> 0 | K44: =IF($X$12="Cost Savings",K35,0) -> 0 | L44: =IF($X$12="Cost Savings",L35,0) -> 0 | M44: =IF($X$12="Cost Savings",M35,0) -> 0 | ... BE44: =IF($X$12="Cost Savings",BE35,0) -> 0
B45: Cost Actual | F45: =IF($X$12="Cost Savings",F36,0) -> 0 | G45: =IF($X$12="Cost Savings",G36,0) -> 0 | H45: =IF($X$12="Cost Savings",H36,0) -> 0 | I45: =IF($X$12="Cost Savings",I36,0) -> 0 | J45: =IF($X$12="Cost Savings",J36,0) -> 0 | K45: =IF($X$12="Cost Savings",K36,0) -> 0 | L45: =IF($X$12="Cost Savings",L36,0) -> 0 | M45: =IF($X$12="Cost Savings",M36,0) -> 0 | ... BE45: =IF($X$12="Cost Savings",BE36,0) -> 0
B47: Financial Target | F47: =F41+F44 -> 0 | G47: =G41+G44 -> 0 | H47: =H41+H44 -> 0 | I47: =I41+I44 -> 0 | J47: =J41+J44 -> 0 | K47: =K41+K44 -> 0 | L47: =L41+L44 -> 0 | M47: =M41+M44 -> 0 | ... BE47: =BE41+BE44 -> 0
B48: Financial Actual | F48: =F42+F45 -> 0 | G48: =G42+G45 -> 0 | H48: =H42+H45 -> 0 | I48: =I42+I45 -> 0 | J48: =J42+J45 -> 0 | K48: =K42+K45 -> 0 | L48: =L42+L45 -> 0 | M48: =M42+M45 -> 0 | ... BE48: =BE42+BE45 -> 0
E49: To Date
...

Sheet P5
B3: PROJECT | AG3: Strategic Value | AO3: =F8 | AV3: =IF(F7="",0,VLOOKUP(F7,Lookups!B4:H8,3)) -> 0 | AZ3: =NOW() -> 45961.687
AG4: Stage Multiplier (today) | AO4: =VLOOKUP(COUNTIF(AR10:AT21,"<="&AZ3),Table3357[],2) -> Not Def | AV4: =IF(AO4="Not Def",0,VLOOKUP(AO4,Lookups!L4:M8,2)) -> 0 | AZ4: Current Qtr | BC4: =VLOOKUP((YEAR(AZ3)&"-"&MONTH(AZ3)),Lookups!S3:U21,2) -> 2025-Q4
B5: Description (Use Case) | AG5: Stage Last Quarter | AO5: =VLOOKUP(COUNTIF(AR10:AT21,"<"&VLOOKUP(BC4,Lookups!W3:Y9,2)),Table3357[],2) -> Not Def | AQ5: =IF(AV5=1,"No Change","Progression") -> Progression | AV5: =IF(AO4="Not Def",0,IF(AO5=AO4,1,1.2)) -> 0
AG6: PROJECT SCORE | AV6: =AV3*AV4*AV5 -> 0
B7: Category | Y7: Ratio Impacted
B8: Strategic Value Level | F8: =IF(F7="","",VLOOKUP(F7,Lookups!B4:H8,2))
B9: Examples | F9: =IF(F7="","",VLOOKUP(F7,Lookups!B4:H8,4)) | AG9: Stage | AJ9: Tasks | AO9: Target | AR9: Completed | AU9: Days to Target | AY9: Notes
