Workbook

Sheet Scorecard
B2: Business Name Here
B4: # | C4: Portfolio | D4: Contact | E4: Company | F4: Initiative | G4: Last Qtr Status | H4: Status | I4: Strategic Value Level | J4: Business Problem Solved | K4: Ratio Impacted | L4: KPI Metric | M4: Financial Target | N4: Financial Actual | O4: Strategic Value Pts | P4: Status Weight | Q4: Progress Value | R4: Total Score
B5: Sample | C5: =IF(F5="","","PYXiS") -> PYXiS | D5: =IF(F5="","",'P1'!$C$17) -> jamie.collingwood@pyxissoftware.com | E5: =IF(D5="","",B$2) -> Business Name Here | F5: =IF('P1'!$F$3="","",'P1'!$F$3) -> Advanced Email Campaigns | G5: =IF(F5="","",'P1'!$AO$5) -> Dev | H5: =IF(F5="","",'P1'!$AO$4) -> Live | I5: ='P1'!$F$8 -> Complex Tool | J5: ='P1'!$F$5 -> hyperpersonalized email campaigns | K5: ='P1'!$AC$7 -> Maintenance | L5: ='P1'!$G$13 -> Revenue Growth from AI-enhanced products | M5: ='P1'!$BE$33*1000 -> 250000 | N5: ='P1'!$E$48*1000 -> 0 | O5: ='P1'!$AV$3 -> 25 | P5: ='P1'!$AV$4 -> 1 | Q5: ='P1'!$AV$5 -> 1.2 | R5: =O5*P5*Q5 -> 30
B6: 1 | C6: =IF(F6="","","PYXiS") | D6: =IF(F6="","",Sample!$C$17) | E6: =IF(F6="","",B$2) | F6: =IF(Sample!$F$3="","",Sample!$F$3) | G6: =IF(F6="","",Sample!$AO$5) | H6: =IF(F6="","",Sample!$AO$4) | I6: =IF(F6="","",Sample!$F$8) | J6: =IF(F6="","",Sample!$F$5) | K6: =IF(F6="","",Sample!$AC$7) | L6: =IF(F6="","",Sample!$G$13) | M6: =Sample!$BE$33*1000 -> 0 | N6: =Sample!$E$48*1000 -> 0 | O6: =Sample!$AV$3 -> 10 | P6: =Sample!$AV$4 -> 0 | Q6: =Sample!$AV$5 -> 0 | R6: =O6*P6*Q6 -> 0
B7: 2 | C7: =IF(F7="","","PYXiS") | D7: =IF(F7="","",'P2'!$C$17) | E7: =IF(F7="","",B$2) | F7: =IF('P2'!$F$3="","",'P2'!$F$3) | G7: =IF(F7="","",'P2'!$AO$5) | H7: =IF(F7="","",'P2'!$AO$4) | I7: =IF(F7="","",'P2'!$F$8) | J7: =IF(F7="","",'P2'!$F$5) | K7: =IF(F7="","",'P2'!$AC$7) | L7: =IF(F7="","",'P2'!$G$13) | M7: ='P2'!$BE$33*1000 -> 0 | N7: ='P2'!$E$48*1000 -> 0 | O7: ='P2'!$AV$3 -> 0 | P7: ='P2'!$AV$4 -> 0 | Q7: ='P2'!$AV$5 -> 0 | R7: =O7*P7*Q7 -> 0
B8: 3 | C8: =IF(F8="","","PYXiS") | D8: =IF(F8="","",'P3'!$C$17) | E8: =IF(F8="","",B$2) | F8: =IF('P3'!$F$3="","",'P3'!$F$3) | G8: =IF(F8="","",'P3'!$AO$5) | H8: =IF(F8="","",'P3'!$AO$4) | I8: =IF(F8="","",'P3'!$F$8) | J8: =IF(F8="","",'P3'!$F$5) | K8: =IF(F8="","",'P3'!$AC$7) | L8: =IF(F8="","",'P3'!$G$13) | M8: ='P3'!$BE$33*1000 -> 0 | N8: ='P3'!$E$48*1000 -> 0 | O8: ='P3'!$AV$3 -> 0 | P8: ='P3'!$AV$4 -> 0 | Q8: ='P3'!$AV$5 -> 0 | R8: =O8*P8*Q8 -> 0
B9: 4 | C9: =IF(F9="","","PYXiS") | D9: =IF(F9="","",'P4'!$C$17) | E9: =IF(F9="","",B$2) | F9: =IF('P4'!$F$3="","",'P4'!$F$3) | G9: =IF(F9="","",'P4'!$AO$5) | H9: =IF(F9="","",'P4'!$AO$4) | I9: =IF(F9="","",'P4'!$F$8) | J9: =IF(F9="","",'P4'!$F$5) | K9: =IF(F9="","",'P4'!$AC$7) | L9: =IF(F9="","",'P4'!$G$13) | M9: ='P4'!$BE$33*1000 -> 0 | N9: ='P4'!$E$48*1000 -> 0 | O9: ='P4'!$AV$3 -> 0 | P9: ='P4'!$AV$4 -> 0 | Q9: ='P4'!$AV$5 -> 0 | R9: =O9*P9*Q9 -> 0
B10: 5 | C10: =IF(F10="","","PYXiS") | D10: =IF(F10="","",[1]P5!$C$17) | E10: =IF(F10="","",B$2) | F10: =IF('P5'!$F$3="","",'P5'!$F$3) | G10: =IF(F10="","",'P5'!$AO$5) | H10: =IF(F10="","",'P5'!$AO$4) | I10: =IF(F10="","",'P5'!$F$8) | J10: =IF(F10="","",'P5'!$F$5) | K10: =IF(F10="","",'P5'!$AC$7) | L10: =IF(F10="","",'P5'!$G$13) | M10: ='P5'!$BE$33*1000 -> 0 | N10: ='P5'!$E$48*1000 -> 0 | O10: ='P5'!$AV$3 -> 0 | P10: ='P5'!$AV$4 -> 0 | Q10: ='P5'!$AV$5 -> 0 | R10: =O10*P50*Q10 -> 0
B11: 6 | C11: =IF(F11="","","PYXiS") | D11: =IF(F11="","",'P6'!$C$17) | E11: =IF(F11="","",B$2) | F11: =IF('P6'!$F$3="","",'P6'!$F$3) | G11: =IF(F11="","",'P6'!$AO$5) | H11: =IF(F11="","",'P6'!$AO$4) | I11: =IF(F11="","",'P6'!$F$8) | J11: =IF(F11="","",'P6'!$F$5) | K11: =IF(F11="","",'P6'!$AC$7) | L11: =IF(F11="","",'P6'!$G$13) | M11: ='P6'!$BE$33*1000 -> 0 | N11: ='P6'!$E$48*1000 -> 0 | O11: ='P6'!$AV$3 -> 0 | P11: ='P6'!$AV$4 -> 0 | Q11: ='P6'!$AV$5 -> 0 | R11: =O11*P61*Q11 -> 0
B12: 7 | C12: =IF(F12="","","PYXiS") | D12: =IF(F12="","",'P7'!$C$17) | E12: =IF(F12="","",B$2) | F12: =IF('P7'!$F$3="","",'P7'!$F$3) | G12: =IF(F12="","",'P7'!$AO$5) | H12: =IF(F12="","",'P7'!$AO$4) | I12: =IF(F12="","",'P7'!$F$8) | J12: =IF(F12="","",'P7'!$F$5) | K12: =IF(F12="","",'P7'!$AC$7) | L12: =IF(F12="","",'P7'!$G$13) | M12: ='P7'!$BE$33*1000 -> 0 | N12: ='P7'!$E$48*1000 -> 0 | O12: ='P7'!$AV$3 -> 0 | P12: ='P7'!$AV$4 -> 0 | Q12: ='P7'!$AV$5 -> 0 | R12: =O12*P72*Q12 -> 0
B13: 8 | C13: =IF(F13="","","PYXiS") | D13: =IF(F13="","",'P8'!$C$17) | E13: =IF(F13="","",B$2) | F13: =IF('P8'!$F$3="","",'P8'!$F$3) | G13: =IF(F13="","",'P8'!$AO$5) | H13: =IF(F13="","",'P8'!$AO$4) | I13: =IF(F13="","",'P8'!$F$8) | J13: =IF(F13="","",'P8'!$F$5) | K13: =IF(F13="","",'P8'!$AC$7) | L13: =IF(F13="","",'P8'!$G$13) | M13: ='P8'!$BE$33*1000 -> 0 | N13: ='P8'!$E$48*1000 -> 0 | O13: ='P8'!$AV$3 -> 0 | P13: ='P8'!$AV$4 -> 0 | Q13: ='P8'!$AV$5 -> 0 | R13: =O13*P83*Q13 -> 0
B14: 9 | C14: =IF(F14="","","PYXiS") | D14: =IF(F14="","",'P9'!$C$17) | E14: =IF(F14="","",B$2) | F14: =IF('P9'!$F$3="","",'P9'!$F$3) | G14: =IF(F14="","",'P9'!$AO$5) | H14: =IF(F14="","",'P9'!$AO$4) | I14: =IF(F14="","",'P9'!$F$8) | J14: =IF(F14="","",'P9'!$F$5) | K14: =IF(F14="","",'P9'!$AC$7) | L14: =IF(F14="","",'P9'!$G$13) | M14: ='P9'!$BE$33*1000 -> 0 | N14: ='P9'!$E$48*1000 -> 0 | O14: ='P9'!$AV$3 -> 0 | P14: ='P9'!$AV$4 -> 0 | Q14: ='P9'!$AV$5 -> 0 | R14: =O14*P94*Q14 -> 0
B15: 10 | C15: =IF(F15="","","PYXiS") | D15: =IF(F15="","",'P10'!$C$17) | E15: =IF(F15="","",B$2) | F15: =IF('P10'!$F$3="","",'P10'!$F$3) | G15: =IF(F15="","",'P10'!$AO$5) | H15: =IF(F15="","",'P10'!$AO$4) | I15: =IF(F15="","",'P10'!$F$8) | J15: =IF(F15="","",'P10'!$F$5) | K15: =IF(F15="","",'P10'!$AC$7) | L15: =IF(F15="","",'P10'!$G$13) | M15: ='P10'!$BE$33*1000 -> 0 | N15: ='P10'!$E$48*1000 -> 0 | O15: ='P10'!$AV$3 -> 0 | P15: ='P10'!$AV$4 -> 0 | Q15: ='P10'!$AV$5 -> 0 | R15: =O15*P105*Q15 -> 0
L16: TOTAL FINANCIAL | M16: =SUM(M6:M15) -> 0 | N16: =SUM(N6:N15) -> 0 | O16: TOTAL AI SCORE FOR BU | R16: =SUM(R6:R15) -> 0

Sheet Sample
B3: PROJECT | AG3: Strategic Value | AO3: =F8 -> Simple Tool | AV3: =IF(F7="",0,VLOOKUP(F7,Lookups!B12:H16,3)) -> 10 | AZ3: =NOW() -> 45957.658
AG4: Stage Multiplier (today) | AO4: =VLOOKUP(COUNTIF(AY10:BA21,"<="&AZ3),Table3357[],2) -> Not Def | AV4: =IF(AO4="Not Def",0,VLOOKUP(AO4,Lookups!L4:M8,2)) -> 0 | AZ4: Current Qtr | BC4: =VLOOKUP((YEAR(AZ3)&"-"&MONTH(AZ3)),Lookups!S3:U21,2) -> 2025-Q4
B5: Description (Use Case) | AG5: Stage Last Quarter | AO5: =VLOOKUP(COUNTIF(AY10:BA21,"<"&VLOOKUP(BC4,Lookups!W3:Y9,2)),Table3357[],2) -> Not Def | AQ5: =IF(AV5=1,"No Change","Progression") -> Progression | AV5: =IF(AO4="Not Def",0,IF(AO5=AO4,1,1.2)) -> 0
AG6: PROJECT SCORE | AV6: =AV3*AV4*AV5 -> 0
B7: Category | F7: L1. Using external AI tools for basic internal productivity | Y7: Ratio Impacted
B8: Strategic Value Level | F8: =IF(F7="","",VLOOKUP(F7,Lookups!B12:H16,2)) -> Simple Tool
B9: Examples | F9: =IF(F7="","",VLOOKUP(F7,Lookups!B12:H16,4)) -> ChatGPT for content, Co-Pilot for drafting emails, AI meeting sunnaries | AG9: Stage | AO9: Tasks | AV9: Target | AY9: Completed | BB9: Days to Target
AG10: Idea | AO10: Project Defined | BB10: =IF(AV10=$BK$3,"Missing Target",IF(AY10=$BK$3,IF($AZ$3>AV10,INT($AZ$3-AV10)&" Day(s) Overdue","Incomplete"),IF(AY10>AV10,INT(AY10-AV10)&" Day(s) Late",IF(AY10=AV10,"OK",INT(AV10-AY10)&" Day(s) Ahead")))) -> Missing Target
B11: PROJECT RESOURCES | F11: KEY PERFORMANCE INDICATORS / MEASURES OF SUCCESS | AO11: Business Case approved | BB11: =IF(AV11=$BK$3,"Missing Target",IF(AY11=$BK$3,IF($AZ$3>AV11,INT($AZ$3-AV11)&" Day(s) Overdue","Incomplete"),IF(AY11>AV11,INT(AY11-AV11)&" Day(s) Late",IF(AY11=AV11,"OK",INT(AV11-AY11)&" Day(s) Ahead")))) -> Missing Target
B12: AI Tools & Services | F12: =IF(F7="","",VLOOKUP(F7,Lookups!B12:H16,5)) -> Adoption Rate | O12: =IF(F7="","",VLOOKUP(F7,Lookups!B12:H16,6)) -> Productivity Gains | X12: =IF(F7="","",VLOOKUP(F7,Lookups!B12:H16,7)) -> Cost Savings | AO12: Resources Allocated | BB12: =IF(AV12=$BK$3,"Missing Target",IF(AY12=$BK$3,IF($AZ$3>AV12,INT($AZ$3-AV12)&" Day(s) Overdue","Incomplete"),IF(AY12>AV12,INT(AY12-AV12)&" Day(s) Late",IF(AY12=AV12,"OK",INT(AV12-AY12)&" Day(s) Ahead")))) -> Missing Target
F13: KPI | G13: Employee Productivity Gains | O13: KPI | P13: Select the primary KPI (Jonas Library) | X13: KPI | Y13: Select the primary KPI (Jonas Library) | AG13: Develop | AO13: Technical PoC validated | BB13: =IF(AV13=$BK$3,"Missing Target",IF(AY13=$BK$3,IF($AZ$3>AV13,INT($AZ$3-AV13)&" Day(s) Overdue","Incomplete"),IF(AY13>AV13,INT(AY13-AV13)&" Day(s) Late",IF(AY13=AV13,"OK",INT(AV13-AY13)&" Day(s) Ahead")))) -> Missing Target
F14: How does this Project support this KPI? | O14: How does this Project support this KPI? | X14: How does this Project support this KPI? | AO14: Dev roadmap documented | BB14: =IF(AV14=$BK$3,"Missing Target",IF(AY14=$BK$3,IF($AZ$3>AV14,INT($AZ$3-AV14)&" Day(s) Overdue","Incomplete"),IF(AY14>AV14,INT(AY14-AV14)&" Day(s) Late",IF(AY14=AV14,"OK",INT(AV14-AY14)&" Day(s) Ahead")))) -> Missing Target
AO15: Coding started | BB15: =IF(AV15=$A$1,"Missing Target",IF(AY15=$A$1,IF($AZ$3>AV15,INT($AZ$3-AV15)&" Day(s) Overdue","Incomplete"),IF(AY15>AV15,INT(AY15-AV15)&" Day(s) Late",IF(AY15=AV15,"OK",INT(AV15-AY15)&" Day(s) Ahead")))) -> Missing Target
AG16: Pilot | AO16: Deployment to beta | BB16: =IF(AV16=$A$1,"Missing Target",IF(AY16=$A$1,IF($AZ$3>AV16,INT($AZ$3-AV16)&" Day(s) Overdue","Incomplete"),IF(AY16>AV16,INT(AY16-AV16)&" Day(s) Late",IF(AY16=AV16,"OK",INT(AV16-AY16)&" Day(s) Ahead")))) -> Missing Target
B17: Contact | AO17: Initial metrics/feedback | BB17: =IF(AV17=$A$1,"Missing Target",IF(AY17=$A$1,IF($AZ$3>AV17,INT($AZ$3-AV17)&" Day(s) Overdue","Incomplete"),IF(AY17>AV17,INT(AY17-AV17)&" Day(s) Late",IF(AY17=AV17,"OK",INT(AV17-AY17)&" Day(s) Ahead")))) -> Missing Target
B18: Prod Mgr | F18: How will you measure the KPI? | O18: How will you measure the KPI? | X18: How will you measure the KPI? | AO18: Feedback affecting code | BB18: =IF(AV18=$A$1,"Missing Target",IF(AY18=$A$1,IF($AZ$3>AV18,INT($AZ$3-AV18)&" Day(s) Overdue","Incomplete"),IF(AY18>AV18,INT(AY18-AV18)&" Day(s) Late",IF(AY18=AV18,"OK",INT(AV18-AY18)&" Day(s) Ahead")))) -> Missing Target
B19: Analyst | AG19: Live | AO19: General release available | BB19: =IF(AV19=$A$1,"Missing Target",IF(AY19=$A$1,IF($AZ$3>AV19,INT($AZ$3-AV19)&" Day(s) Overdue","Incomplete"),IF(AY19>AV19,INT(AY19-AV19)&" Day(s) Late",IF(AY19=AV19,"OK",INT(AV19-AY19)&" Day(s) Ahead")))) -> Missing Target
B20: Tech Lead | AO20: Success mertics tracking | BB20: =IF(AV20=$A$1,"Missing Target",IF(AY20=$A$1,IF($AZ$3>AV20,INT($AZ$3-AV20)&" Day(s) Overdue","Incomplete"),IF(AY20>AV20,INT(AY20-AV20)&" Day(s) Late",IF(AY20=AV20,"OK",INT(AV20-AY20)&" Day(s) Ahead")))) -> Missing Target
B21: Exec | AO21: Feedback loop continuing | BB21: =IF(AV21=$A$1,"Missing Target",IF(AY21=$A$1,IF($AZ$3>AV21,INT($AZ$3-AV21)&" Day(s) Overdue","Incomplete"),IF(AY21>AV21,INT(AY21-AV21)&" Day(s) Late",IF(AY21=AV21,"OK",INT(AV21-AY21)&" Day(s) Ahead")))) -> Missing Target
B23: WEEKLY KPI TRACKER | F23: 1 | G23: =F23+1 -> 2 | H23: =G23+1 -> 3 | I23: =H23+1 -> 4 | J23: =I23+1 -> 5 | K23: =J23+1 -> 6 | L23: =K23+1 -> 7 | M23: =L23+1 -> 8 | N23: =M23+1 -> 9 | ... BE23: =BD23+1 -> 52
B24: Week Ending | F24: =NOW() -> 45957.658 | G24: =F24+7 -> 45964.658 | H24: =G24+7 -> 45971.658 | I24: =H24+7 -> 45978.658 | J24: =I24+7 -> 45985.658 | K24: =J24+7 -> 45992.658 | L24: =K24+7 -> 45999.658 | M24: =L24+7 -> 46006.658 | N24: =M24+7 -> 46013.658 | ... BE24: =BD24+7 -> 46314.658
B25: =G13&" TARGET" -> Employee Productivity Gains TARGET
B26: Actual
B27: Delta | F27: =F26-F25 -> 0 | G27: =G26-G25 -> 0 | H27: =H26-H25 -> 0 | I27: =I26-I25 -> 0 | J27: =J26-J25 -> 0 | K27: =K26-K25 -> 0 | L27: =L26-L25 -> 0 | M27: =M26-M25 -> 0 | ... BE27: =BE26-BE25 -> 0
B29: =P13&" TARGET" -> Select the primary KPI (Jonas Library) TARGET
B30: Actual
B31: Delta | F31: =F30-F29 -> 0 | G31: =G30-G29 -> 0 | H31: =H30-H29 -> 0 | I31: =I30-I29 -> 0 | J31: =J30-J29 -> 0 | K31: =K30-K29 -> 0 | L31: =L30-L29 -> 0 | M31: =M30-M29 -> 0 | ... BE31: =BE30-BE29 -> 0
B33: =Y13&" TARGET" -> Select the primary KPI (Jonas Library) TARGET
B34: Actual
B35: Delta | F35: =F34-F33 -> 0 | G35: =G34-G33 -> 0 | H35: =H34-H33 -> 0 | I35: =I34-I33 -> 0 | J35: =J34-J33 -> 0 | K35: =K34-K33 -> 0 | L35: =L34-L33 -> 0 | M35: =M34-M33 -> 0 | ... BE35: =BE34-BE33 -> 0
B38: Revenue Target | F38: =IF($X$12="Revenue Impact",F33,0) -> 0 | G38: =IF($X$12="Revenue Impact",G33,0) -> 0 | H38: =IF($X$12="Revenue Impact",H33,0) -> 0 | I38: =IF($X$12="Revenue Impact",I33,0) -> 0 | J38: =IF($X$12="Revenue Impact",J33,0) -> 0 | K38: =IF($X$12="Revenue Impact",K33,0) -> 0 | L38: =IF($X$12="Revenue Impact",L33,0) -> 0 | M38: =IF($X$12="Revenue Impact",M33,0) -> 0 | ... BE38: =IF($X$12="Revenue Impact",BE33,0) -> 0
B39: Revenue Actual | F39: =IF($X$12="Revenue Impact",F34,0) -> 0 | G39: =IF($X$12="Revenue Impact",G34,0) -> 0 | H39: =IF($X$12="Revenue Impact",H34,0) -> 0 | I39: =IF($X$12="Revenue Impact",I34,0) -> 0 | J39: =IF($X$12="Revenue Impact",J34,0) -> 0 | K39: =IF($X$12="Revenue Impact",K34,0) -> 0 | L39: =IF($X$12="Revenue Impact",L34,0) -> 0 | M39: =IF($X$12="Revenue Impact",M34,0) -> 0 | ... BE39: =IF($X$12="Revenue Impact",BE34,0) -> 0
B41: Cost Target | F41: =IF($X$12="Cost Savings",F33,0) -> 0 | G41: =IF($X$12="Cost Savings",G33,0) -> 0 | H41: =IF($X$12="Cost Savings",H33,0) -> 0 | I41: =IF($X$12="Cost Savings",I33,0) -> 0 | J41: =IF($X$12="Cost Savings",J33,0) -> 0 | K41: =IF($X$12="Cost Savings",K33,0) -> 0 | L41: =IF($X$12="Cost Savings",L33,0) -> 0 | M41: =IF($X$12="Cost Savings",M33,0) -> 0 | ... BE41: =IF($X$12="Cost Savings",BE33,0) -> 0
B42: Cost Actual | F42: =IF($X$12="Cost Savings",F34,0) -> 0 | G42: =IF($X$12="Cost Savings",G34,0) -> 0 | H42: =IF($X$12="Cost Savings",H34,0) -> 0 | I42: =IF($X$12="Cost Savings",I34,0) -> 0 | J42: =IF($X$12="Cost Savings",J34,0) -> 0 | K42: =IF($X$12="Cost Savings",K34,0) -> 0 | L42: =IF($X$12="Cost Savings",L34,0) -> 0 | M42: =IF($X$12="Cost Savings",M34,0) -> 0 | ... BE42: =IF($X$12="Cost Savings",BE34,0) -> 0
B44: Financial Target | F44: =F38+F41 -> 0 | G44: =G38+G41 -> 0 | H44: =H38+H41 -> 0 | I44: =I38+I41 -> 0 | J44: =J38+J41 -> 0 | K44: =K38+K41 -> 0 | L44: =L38+L41 -> 0 | M44: =M38+M41 -> 0 | ... BE44: =BE38+BE41 -> 0
B45: Financial Actual | F45: =F39+F42 -> 0 | G45: =G39+G42 -> 0 | H45: =H39+H42 -> 0 | I45: =I39+I42 -> 0 | J45: =J39+J42 -> 0 | K45: =K39+K42 -> 0 | L45: =L39+L42 -> 0 | M45: =M39+M42 -> 0 | ... BE45: =BE39+BE42 -> 0
E46: To Date
B47: Current Financial Target | E47: =MAX(F47:BE47) -> 0 | F47: =IF($AZ$3>F24,F44,0) -> 0 | G47: =IF($AZ$3>G24,G44,0) -> 0 | H47: =IF($AZ$3>H24,H44,0) -> 0 | I47: =IF($AZ$3>I24,I44,0) -> 0 | J47: =IF($AZ$3>J24,J44,0) -> 0 | K47: =IF($AZ$3>K24,K44,0) -> 0 | L47: =IF($AZ$3>L24,L44,0) -> 0 | M47: =IF($AZ$3>M24,M44,0) -> 0 | ... BE47: =IF($AZ$3>BE24,BE44,0) -> 0
B48: Current Financial Actual | E48: =MAX(F48:BE48) -> 0 | F48: =IF($AZ$3>F25,F45,0) -> 0 | G48: =IF($AZ$3>G25,G45,0) -> 0 | H48: =IF($AZ$3>H25,H45,0) -> 0 | I48: =IF($AZ$3>I25,I45,0) -> 0 | J48: =IF($AZ$3>J25,J45,0) -> 0 | K48: =IF($AZ$3>K25,K45,0) -> 0 | L48: =IF($AZ$3>L25,L45,0) -> 0 | M48: =IF($AZ$3>M25,M45,0) -> 0 | ... BE48: =IF($AZ$3>BE25,BE45,0) -> 0

Sheet P1
B3: PROJECT | F3: Advanced Email Campaigns | AG3: Strategic Value | AO3: =F8 -> Complex Tool | AV3: =IF(F7="",0,VLOOKUP(F7,Lookups!B12:H16,3)) -> 25 | AZ3: =NOW() -> 45957.658
AG4: Stage Multiplier (today) | AO4: =VLOOKUP(COUNTIF(AY10:BA21,"<="&AZ3),Table3357[],2) -> Live | AV4: =VLOOKUP(AO4,Lookups!L4:M8,2) -> 1 | AZ4: Current Qtr | BC4: =VLOOKUP((YEAR(AZ3)&"-"&MONTH(AZ3)),Lookups!S3:U21,2) -> 2025-Q4
B5: Description (Use Case) | F5: hyperpersonalized email campaigns | AG5: Stage Last Quarter | AO5: =VLOOKUP(COUNTIF(AY10:BA21,"<"&VLOOKUP(BC4,Lookups!W3:Y9,2)),Table3357[],2) -> Dev | AQ5: =IF(AV5=1,"No Change","Progression") -> Progression | AV5: =IF(AO5=AO4,1,1.2) -> 1.2
AG6: PROJECT SCORE | AV6: =AV3*AV4*AV5 -> 30
B7: Category | F7: L2. Sophisticated AI tooling for developnent/operations but generally limited to a single departnent or workflow | Y7: Ratio Impacted | AC7: Maintenance
B8: Strategic Value Level | F8: =IF(F7="","",VLOOKUP(F7,Lookups!B12:H16,2)) -> Complex Tool
B9: Examples | F9: =IF(F7="","",VLOOKUP(F7,Lookups!B12:H16,4)) -> AI-powered code review, automated testing, advanced development environments | AG9: Stage | AO9: Tasks | AV9: Target | AY9: Completed | BB9: Days to Target
AG10: Idea | AO10: Project Defined | AV10: 45884 | AY10: 45885 | BB10: =IF(AV10=$BK$3,"Missing Target",IF(AY10=$BK$3,IF($AZ$3>AV10,INT($AZ$3-AV10)&" Day(s) Overdue","Incomplete"),IF(AY10>AV10,INT(AY10-AV10)&" Day(s) Late",IF(AY10=AV10,"OK",INT(AV10-AY10)&" Day(s) Ahead")))) -> 1 Day(s) Late
B11: PROJECT RESOURCES | F11: KEY PERFORMANCE INDICATORS / MEASURES OF SUCCESS | AO11: Business Case approved | AV11: =AV10+7 -> 45891 | AY11: 45901 | BB11: =IF(AV11=$BK$3,"Missing Target",IF(AY11=$BK$3,IF($AZ$3>AV11,INT($AZ$3-AV11)&" Day(s) Overdue","Incomplete"),IF(AY11>AV11,INT(AY11-AV11)&" Day(s) Late",IF(AY11=AV11,"OK",INT(AV11-AY11)&" Day(s) Ahead")))) -> 10 Day(s) Late
B12: AI Tools & Services | F12: =IF(F7="","",VLOOKUP(F7,Lookups!B12:H16,5)) -> Integration Depth | O12: =IF(F7="","",VLOOKUP(F7,Lookups!B12:H16,6)) -> Process Improvement | X12: =IF(F7="","",VLOOKUP(F7,Lookups!B12:H16,7)) -> Skills Development | AO12: Resources Allocated | AV12: =AV11+7 -> 45898 | AY12: =AV12 -> 45898 | BB12: =IF(AV12=$BK$3,"Missing Target",IF(AY12=$BK$3,IF($AZ$3>AV12,INT($AZ$3-AV12)&" Day(s) Overdue","Incomplete"),IF(AY12>AV12,INT(AY12-AV12)&" Day(s) Late",IF(AY12=AV12,"OK",INT(AV12-AY12)&" Day(s) Ahead")))) -> OK
B13: OrbitAI | F13: KPI | G13: Revenue Growth from AI-enhanced products | O13: KPI | P13: Conversion Rates from AI-powered features | X13: KPI | Y13: Automation Rate | AG13: Develop | AO13: Technical PoC validated | AV13: =AV12+7 -> 45905 | AY13: =AV13+2 -> 45907 | BB13: =IF(AV13=$BK$3,"Missing Target",IF(AY13=$BK$3,IF($AZ$3>AV13,INT($AZ$3-AV13)&" Day(s) Overdue","Incomplete"),IF(AY13>AV13,INT(AY13-AV13)&" Day(s) Late",IF(AY13=AV13,"OK",INT(AV13-AY13)&" Day(s) Ahead")))) -> 2 Day(s) Late
F14: How does this Project support this KPI? | O14: How does this Project support this KPI? | X14: How does this Project support this KPI? | AO14: Dev roadmap documented | AV14: =AV13+7 -> 45912 | AY14: =AV14+7 -> 45919 | BB14: =IF(AV14=$BK$3,"Missing Target",IF(AY14=$BK$3,IF($AZ$3>AV14,INT($AZ$3-AV14)&" Day(s) Overdue","Incomplete"),IF(AY14>AV14,INT(AY14-AV14)&" Day(s) Late",IF(AY14=AV14,"OK",INT(AV14-AY14)&" Day(s) Ahead")))) -> 7 Day(s) Late
F15: Enables revenue growth through enhanced sales processes | O15: AI Camp Bunking solution | X15: AI Camp Bunking solution | AO15: Coding started | AV15: =AV14+7 -> 45919 | AY15: =AY14 -> 45919 | BB15: =IF(AV15=$A$1,"Missing Target",IF(AY15=$A$1,IF($AZ$3>AV15,INT($AZ$3-AV15)&" Day(s) Overdue","Incomplete"),IF(AY15>AV15,INT(AY15-AV15)&" Day(s) Late",IF(AY15=AV15,"OK",INT(AV15-AY15)&" Day(s) Ahead")))) -> OK
AG16: Pilot | AO16: Deployment to beta | AV16: =AV15+7 -> 45926 | AY16: 45931 | BB16: =IF(AV16=$A$1,"Missing Target",IF(AY16=$A$1,IF($AZ$3>AV16,INT($AZ$3-AV16)&" Day(s) Overdue","Incomplete"),IF(AY16>AV16,INT(AY16-AV16)&" Day(s) Late",IF(AY16=AV16,"OK",INT(AV16-AY16)&" Day(s) Ahead")))) -> 5 Day(s) Late
B17: Contact | C17: jamie.collingwood@pyxissoftware.com | AO17: Initial metrics/feedback | AV17: =AV16+7 -> 45933 | AY17: 45932 | BB17: =IF(AV17=$A$1,"Missing Target",IF(AY17=$A$1,IF($AZ$3>AV17,INT($AZ$3-AV17)&" Day(s) Overdue","Incomplete"),IF(AY17>AV17,INT(AY17-AV17)&" Day(s) Late",IF(AY17=AV17,"OK",INT(AV17-AY17)&" Day(s) Ahead")))) -> 1 Day(s) Ahead
B18: Prod Mgr | C18: Jamie Collingwood | F18: How will you measure the KPI? | O18: How will you measure the KPI? | X18: How will you measure the KPI? | AO18: Feedback affecting code | AV18: =AV17+7 -> 45940 | AY18: 45940 | BB18: =IF(AV18=$A$1,"Missing Target",IF(AY18=$A$1,IF($AZ$3>AV18,INT($AZ$3-AV18)&" Day(s) Overdue","Incomplete"),IF(AY18>AV18,INT(AY18-AV18)&" Day(s) Late",IF(AY18=AV18,"OK",INT(AV18-AY18)&" Day(s) Ahead")))) -> OK
B19: Analyst | C19: Chase Winston | F19: Improvements in email response campaigns and meetings booked rates | O19: AI Camp Bunking solution | X19: AI Camp Bunking solution | AG19: Live | AO19: General release available | AV19: =AV18+7 -> 45947 | AY19: 45947 | BB19: =IF(AV19=$A$1,"Missing Target",IF(AY19=$A$1,IF($AZ$3>AV19,INT($AZ$3-AV19)&" Day(s) Overdue","Incomplete"),IF(AY19>AV19,INT(AY19-AV19)&" Day(s) Late",IF(AY19=AV19,"OK",INT(AV19-AY19)&" Day(s) Ahead")))) -> OK
B20: Tech Lead | C20: Jim Peltier | AO20: Success mertics tracking | AV20: =AV19+7 -> 45954 | AY20: 45954 | BB20: =IF(AV20=$A$1,"Missing Target",IF(AY20=$A$1,IF($AZ$3>AV20,INT($AZ$3-AV20)&" Day(s) Overdue","Incomplete"),IF(AY20>AV20,INT(AY20-AV20)&" Day(s) Late",IF(AY20=AV20,"OK",INT(AV20-AY20)&" Day(s) Ahead")))) -> OK
B21: Exec | C21: Sandy Crutcher | AO21: Feedback loop continuing | AV21: =AV20+7 -> 45961 | BB21: =IF(AV21=$A$1,"Missing Target",IF(AY21=$A$1,IF($AZ$3>AV21,INT($AZ$3-AV21)&" Day(s) Overdue","Incomplete"),IF(AY21>AV21,INT(AY21-AV21)&" Day(s) Late",IF(AY21=AV21,"OK",INT(AV21-AY21)&" Day(s) Ahead")))) -> Incomplete
B23: WEEKLY KPI TRACKER | F23: 1 | G23: =F23+1 -> 2 | H23: =G23+1 -> 3 | I23: =H23+1 -> 4 | J23: =I23+1 -> 5 | K23: =J23+1 -> 6 | L23: =K23+1 -> 7 | M23: =L23+1 -> 8 | N23: =M23+1 -> 9 | ... BE23: =BD23+1 -> 52
B24: Week Ending | F24: 45884 | G24: =F24+7 -> 45891 | H24: =G24+7 -> 45898 | I24: =H24+7 -> 45905 | J24: =I24+7 -> 45912 | K24: =J24+7 -> 45919 | L24: =K24+7 -> 45926 | M24: =L24+7 -> 45933 | N24: =M24+7 -> 45940 | ... BE24: =BD24+7 -> 46241
B25: =G13&" TARGET" -> Revenue Growth from AI-enhanced products TARGET | F25: 23 | G25: =F25 -> 23 | H25: =G25 -> 23 | I25: =H25 -> 23 | J25: =I25 -> 23 | K25: =J25 -> 23 | L25: =K25 -> 23 | M25: =L25 -> 23 | N25: 60 | O25: 60 | P25: 65 | Q25: 65 | R25: 66 | S25: 67 | T25: 68 | U25: 69 | V25: 70 | W25: 71 | X25: 72 | Y25: 73 | Z25: 74 | AA25: 75 | AB25: 76 | AC25: 77 | AD25: 78 | AE25: 79 | AF25: 80 | AG25: 80 | AH25: 80 | AI25: 80 | AJ25: 80 | AK25: 80 | AL25: 80 | AM25: 80 | AN25: 80 | AO25: 80 | AP25: 80 | AQ25: 80 | AR25: 80 | AS25: 80 | AT25: 80 | AU25: 80 | AV25: 80 | AW25: 80 | AX25: 80 | AY25: 80 | AZ25: 80 | BA25: 80 | BB25: 80 | BC25: 80 | BD25: 80 | BE25: 80
B26: Actual | F26: 25 | G26: 26 | H26: 27 | I26: 28 | J26: 28 | K26: 55 | L26: 55 | M26: 57 | N26: 61
B27: Delta | F27: =F26-F25 -> 2 | G27: =G26-G25 -> 3 | H27: =H26-H25 -> 4 | I27: =I26-I25 -> 5 | J27: =J26-J25 -> 5 | K27: =K26-K25 -> 32 | L27: =L26-L25 -> 32 | M27: =M26-M25 -> 34 | ... BE27: =BE26-BE25 -> -80
B29: =P13&" TARGET" -> Conversion Rates from AI-powered features TARGET | F29: 1 | G29: 2 | H29: 3 | L29: 2 | M29: 2 | N29: 2 | O29: 2 | P29: 2 | Q29: 5 | R29: 5 | S29: 5 | T29: 5 | U29: 5 | V29: 10 | W29: 10 | X29: 10 | Y29: 10 | Z29: 10 | AA29: 15 | AB29: 15 | AC29: 15 | AD29: 15 | AE29: 20 | AF29: 20 | AG29: 20 | AH29: 20 | AI29: 25 | AJ29: 25 | AK29: 25 | AL29: 25 | AM29: 25 | AN29: 25 | AO29: 25 | AP29: 25 | AQ29: 25 | AR29: 25 | AS29: 25 | AT29: 25 | AU29: 25 | AV29: 25 | AW29: 25 | AX29: 25 | AY29: 25 | AZ29: 25 | BA29: 25 | BB29: 25 | BC29: 25 | BD29: 25 | BE29: 25
B30: Actual | F30: 2 | G30: 2 | H30: 2 | I30: 0 | J30: 0 | K30: 0 | L30: 0 | M30: 1 | N30: 1
B31: Delta | F31: =F30-F29 -> 1 | G31: =G30-G29 -> 0 | H31: =H30-H29 -> -1 | I31: =I30-I29 -> 0 | J31: =J30-J29 -> 0 | K31: =K30-K29 -> 0 | L31: =L30-L29 -> -2 | M31: =M30-M29 -> -1 | ... BE31: =BE30-BE29 -> -25
B33: =Y13&" TARGET" -> Automation Rate TARGET | P33: 50 | Q33: =P33 -> 50 | R33: =Q33 -> 50 | S33: =R33 -> 50 | T33: =S33 -> 50 | U33: 100 | V33: =U33 -> 100 | W33: =V33 -> 100 | X33: =W33 -> 100 | Y33: =X33 -> 100 | Z33: =Y33 -> 100 | AA33: =Z33 -> 100 | AB33: 150 | AC33: =AB33 -> 150 | AD33: =AC33 -> 150 | AE33: =AD33 -> 150 | AF33: =AE33 -> 150 | AG33: =AF33 -> 150 | AH33: =AG33 -> 150 | AI33: =AH33 -> 150 | AJ33: 250 | AK33: =AJ33 -> 250 | AL33: =AK33 -> 250 | AM33: =AL33 -> 250 | AN33: =AM33 -> 250 | AO33: =AN33 -> 250 | AP33: =AO33 -> 250 | AQ33: =AP33 -> 250 | AR33: =AQ33 -> 250 | ... BE33: =BD33 -> 250
B34: Actual | F34: 0 | G34: 0 | H34: 0 | I34: 0 | J34: 0 | K34: 0 | L34: 0 | M34: 0
B35: Delta | F35: =F34-F33 -> 0 | G35: =G34-G33 -> 0 | H35: =H34-H33 -> 0 | I35: =I34-I33 -> 0 | J35: =J34-J33 -> 0 | K35: =K34-K33 -> 0 | L35: =L34-L33 -> 0 | M35: =M34-M33 -> 0 | ... BE35: =BE34-BE33 -> -250
B38: Revenue Target | F38: =IF($X$12="Revenue Impact",F33,0) -> 0 | G38: =IF($X$12="Revenue Impact",G33,0) -> 0 | H38: =IF($X$12="Revenue Impact",H33,0) -> 0 | I38: =IF($X$12="Revenue Impact",I33,0) -> 0 | J38: =IF($X$12="Revenue Impact",J33,0) -> 0 | K38: =IF($X$12="Revenue Impact",K33,0) -> 0 | L38: =IF($X$12="Revenue Impact",L33,0) -> 0 | M38: =IF($X$12="Revenue Impact",M33,0) -> 0 | ... BE38: =IF($X$12="Revenue Impact",BE33,0) -> 0
B39: Revenue Actual | F39: =IF($X$12="Revenue Impact",F34,0) -> 0 | G39: =IF($X$12="Revenue Impact",G34,0) -> 0 | H39: =IF($X$12="Revenue Impact",H34,0) -> 0 | I39: =IF($X$12="Revenue Impact",I34,0) -> 0 | J39: =IF($X$12="Revenue Impact",J34,0) -> 0 | K39: =IF($X$12="Revenue Impact",K34,0) -> 0 | L39: =IF($X$12="Revenue Impact",L34,0) -> 0 | M39: =IF($X$12="Revenue Impact",M34,0) -> 0 | ... BE39: =IF($X$12="Revenue Impact",BE34,0) -> 0
B41: Cost Target | F41: =IF($X$12="Cost Savings",F33,0) -> 0 | G41: =IF($X$12="Cost Savings",G33,0) -> 0 | H41: =IF($X$12="Cost Savings",H33,0) -> 0 | I41: =IF($X$12="Cost Savings",I33,0) -> 0 | J41: =IF($X$12="Cost Savings",J33,0) -> 0 | K41: =IF($X$12="Cost Savings",K33,0) -> 0 | L41: =IF($X$12="Cost Savings",L33,0) -> 0 | M41: =IF($X$12="Cost Savings",M33,0) -> 0 | ... BE41: =IF($X$12="Cost Savings",BE33,0) -> 0
B42: Cost Actual | F42: =IF($X$12="Cost Savings",F34,0) -> 0 | G42: =IF($X$12="Cost Savings",G34,0) -> 0 | H42: =IF($X$12="Cost Savings",H34,0) -> 0 | I42: =IF($X$12="Cost Savings",I34,0) -> 0 | J42: =IF($X$12="Cost Savings",J34,0) -> 0 | K42: =IF($X$12="Cost Savings",K34,0) -> 0 | L42: =IF($X$12="Cost Savings",L34,0) -> 0 | M42: =IF($X$12="Cost Savings",M34,0) -> 0 | ... BE42: =IF($X$12="Cost Savings",BE34,0) -> 0
B44: Financial Target | F44: =F38+F41 -> 0 | G44: =G38+G41 -> 0 | H44: =H38+H41 -> 0 | I44: =I38+I41 -> 0 | J44: =J38+J41 -> 0 | K44: =K38+K41 -> 0 | L44: =L38+L41 -> 0 | M44: =M38+M41 -> 0 | ... BE44: =BE38+BE41 -> 0
B45: Financial Actual | F45: =F39+F42 -> 0 | G45: =G39+G42 -> 0 | H45: =H39+H42 -> 0 | I45: =I39+I42 -> 0 | J45: =J39+J42 -> 0 | K45: =K39+K42 -> 0 | L45: =L39+L42 -> 0 | M45: =M39+M42 -> 0 | ... BE45: =BE39+BE42 -> 0
E46: To Date
B47: Current Financial Target | E47: =MAX(F47:BE47) -> 0 | F47: =IF($AZ$3>F24,F44,0) -> 0 | G47: =IF($AZ$3>G24,G44,0) -> 0 | H47: =IF($AZ$3>H24,H44,0) -> 0 | I47: =IF($AZ$3>I24,I44,0) -> 0 | J47: =IF($AZ$3>J24,J44,0) -> 0 | K47: =IF($AZ$3>K24,K44,0) -> 0 | L47: =IF($AZ$3>L24,L44,0) -> 0 | M47: =IF($AZ$3>M24,M44,0) -> 0 | ... BE47: =IF($AZ$3>BE24,BE44,0) -> 0
B48: Current Financial Actual | E48: =MAX(F48:BE48) -> 0 | F48: =IF($AZ$3>F25,F45,0) -> 0 | G48: =IF($AZ$3>G25,G45,0) -> 0 | H48: =IF($AZ$3>H25,H45,0) -> 0 | I48: =IF($AZ$3>I25,I45,0) -> 0 | J48: =IF($AZ$3>J25,J45,0) -> 0 | K48: =IF($AZ$3>K25,K45,0) -> 0 | L48: =IF($AZ$3>L25,L45,0) -> 0 | M48: =IF($AZ$3>M25,M45,0) -> 0 | ... BE48: =IF($AZ$3>BE25,BE45,0) -> 0

Sheet P2
B3: PROJECT | AG3: Strategic Value | AO3: =F8 | AV3: =IF(F7="",0,VLOOKUP(F7,Lookups!B12:H16,3)) -> 0 | AZ3: =NOW() -> 45957.658
AG4: Stage Multiplier (today) | AO4: =VLOOKUP(COUNTIF(AY10:BA21,"<="&AZ3),Table3357[],2) -> Not Def | AV4: =IF(AO4="Not Def",0,VLOOKUP(AO4,Lookups!L4:M8,2)) -> 0 | AZ4: Current Qtr | BC4: =VLOOKUP((YEAR(AZ3)&"-"&MONTH(AZ3)),Lookups!S3:U21,2) -> 2025-Q4
B5: Description (Use Case) | AG5: Stage Last Quarter | AO5: =VLOOKUP(COUNTIF(AY10:BA21,"<"&VLOOKUP(BC4,Lookups!W3:Y9,2)),Table3357[],2) -> Not Def | AQ5: =IF(AV5=1,"No Change","Progression") -> Progression | AV5: =IF(AO4="Not Def",0,IF(AO5=AO4,1,1.2)) -> 0
AG6: PROJECT SCORE | AV6: =AV3*AV4*AV5 -> 0
B7: Category | Y7: Ratio Impacted
B8: Strategic Value Level | F8: =IF(F7="","",VLOOKUP(F7,Lookups!B12:H16,2))
B9: Examples | F9: =IF(F7="","",VLOOKUP(F7,Lookups!B12:H16,4)) | AG9: Stage | AO9: Tasks | AV9: Target | AY9: Completed | BB9: Days to Target
AG10: Idea | AO10: Project Defined | BB10: =IF(AV10=$BK$3,"Missing Target",IF(AY10=$BK$3,IF($AZ$3>AV10,INT($AZ$3-AV10)&" Day(s) Overdue","Incomplete"),IF(AY10>AV10,INT(AY10-AV10)&" Day(s) Late",IF(AY10=AV10,"OK",INT(AV10-AY10)&" Day(s) Ahead")))) -> Missing Target
B11: PROJECT RESOURCES | F11: KEY PERFORMANCE INDICATORS / MEASURES OF SUCCESS | AO11: Business Case approved | BB11: =IF(AV11=$BK$3,"Missing Target",IF(AY11=$BK$3,IF($AZ$3>AV11,INT($AZ$3-AV11)&" Day(s) Overdue","Incomplete"),IF(AY11>AV11,INT(AY11-AV11)&" Day(s) Late",IF(AY11=AV11,"OK",INT(AV11-AY11)&" Day(s) Ahead")))) -> Missing Target
B12: AI Tools & Services | F12: =IF(F7="","",VLOOKUP(F7,Lookups!B12:H16,5)) | O12: =IF(F7="","",VLOOKUP(F7,Lookups!B12:H16,6)) | X12: =IF(F7="","",VLOOKUP(F7,Lookups!B12:H16,7)) | AO12: Resources Allocated | BB12: =IF(AV12=$BK$3,"Missing Target",IF(AY12=$BK$3,IF($AZ$3>AV12,INT($AZ$3-AV12)&" Day(s) Overdue","Incomplete"),IF(AY12>AV12,INT(AY12-AV12)&" Day(s) Late",IF(AY12=AV12,"OK",INT(AV12-AY12)&" Day(s) Ahead")))) -> Missing Target
F13: KPI | G13: Select the primary KPI (Jonas Library) | O13: KPI | P13: Select the primary KPI (Jonas Library) | X13: KPI | Y13: Select the primary KPI (Jonas Library) | AG13: Develop | AO13: Technical PoC validated | BB13: =IF(AV13=$BK$3,"Missing Target",IF(AY13=$BK$3,IF($AZ$3>AV13,INT($AZ$3-AV13)&" Day(s) Overdue","Incomplete"),IF(AY13>AV13,INT(AY13-AV13)&" Day(s) Late",IF(AY13=AV13,"OK",INT(AV13-AY13)&" Day(s) Ahead")))) -> Missing Target
F14: How does this Project support this KPI? | O14: How does this Project support this KPI? | X14: How does this Project support this KPI? | AO14: Dev roadmap documented | BB14: =IF(AV14=$BK$3,"Missing Target",IF(AY14=$BK$3,IF($AZ$3>AV14,INT($AZ$3-AV14)&" Day(s) Overdue","Incomplete"),IF(AY14>AV14,INT(AY14-AV14)&" Day(s) Late",IF(AY14=AV14,"OK",INT(AV14-AY14)&" Day(s) Ahead")))) -> Missing Target
AO15: Coding started | BB15: =IF(AV15=$A$1,"Missing Target",IF(AY15=$A$1,IF($AZ$3>AV15,INT($AZ$3-AV15)&" Day(s) Overdue","Incomplete"),IF(AY15>AV15,INT(AY15-AV15)&" Day(s) Late",IF(AY15=AV15,"OK",INT(AV15-AY15)&" Day(s) Ahead")))) -> Missing Target
AG16: Pilot | AO16: Deployment to beta | BB16: =IF(AV16=$A$1,"Missing Target",IF(AY16=$A$1,IF($AZ$3>AV16,INT($AZ$3-AV16)&" Day(s) Overdue","Incomplete"),IF(AY16>AV16,INT(AY16-AV16)&" Day(s) Late",IF(AY16=AV16,"OK",INT(AV16-AY16)&" Day(s) Ahead")))) -> Missing Target
B17: Contact | AO17: Initial metrics/feedback | BB17: =IF(AV17=$A$1,"Missing Target",IF(AY17=$A$1,IF($AZ$3>AV17,INT($AZ$3-AV17)&" Day(s) Overdue","Incomplete"),IF(AY17>AV17,INT(AY17-AV17)&" Day(s) Late",IF(AY17=AV17,"OK",INT(AV17-AY17)&" Day(s) Ahead")))) -> Missing Target
B18: Prod Mgr | F18: How will you measure the KPI? | O18: How will you measure the KPI? | X18: How will you measure the KPI? | AO18: Feedback affecting code | BB18: =IF(AV18=$A$1,"Missing Target",IF(AY18=$A$1,IF($AZ$3>AV18,INT($AZ$3-AV18)&" Day(s) Overdue","Incomplete"),IF(AY18>AV18,INT(AY18-AV18)&" Day(s) Late",IF(AY18=AV18,"OK",INT(AV18-AY18)&" Day(s) Ahead")))) -> Missing Target
B19: Analyst | AG19: Live | AO19: General release available | BB19: =IF(AV19=$A$1,"Missing Target",IF(AY19=$A$1,IF($AZ$3>AV19,INT($AZ$3-AV19)&" Day(s) Overdue","Incomplete"),IF(AY19>AV19,INT(AY19-AV19)&" Day(s) Late",IF(AY19=AV19,"OK",INT(AV19-AY19)&" Day(s) Ahead")))) -> Missing Target
B20: Tech Lead | AO20: Success mertics tracking | BB20: =IF(AV20=$A$1,"Missing Target",IF(AY20=$A$1,IF($AZ$3>AV20,INT($AZ$3-AV20)&" Day(s) Overdue","Incomplete"),IF(AY20>AV20,INT(AY20-AV20)&" Day(s) Late",IF(AY20=AV20,"OK",INT(AV20-AY20)&" Day(s) Ahead")))) -> Missing Target
B21: Exec | AO21: Feedback loop continuing | BB21: =IF(AV21=$A$1,"Missing Target",IF(AY21=$A$1,IF($AZ$3>AV21,INT($AZ$3-AV21)&" Day(s) Overdue","Incomplete"),IF(AY21>AV21,INT(AY21-AV21)&" Day(s) Late",IF(AY21=AV21,"OK",INT(AV21-AY21)&" Day(s) Ahead")))) -> Missing Target
B23: WEEKLY KPI TRACKER | F23: 1 | G23: =F23+1 -> 2 | H23: =G23+1 -> 3 | I23: =H23+1 -> 4 | J23: =I23+1 -> 5 | K23: =J23+1 -> 6 | L23: =K23+1 -> 7 | M23: =L23+1 -> 8 | N23: =M23+1 -> 9 | ... BE23: =BD23+1 -> 52
B24: Week Ending | F24: =NOW() -> 45957.658 | G24: =F24+7 -> 45964.658 | H24: =G24+7 -> 45971.658 | I24: =H24+7 -> 45978.658 | J24: =I24+7 -> 45985.658 | K24: =J24+7 -> 45992.658 | L24: =K24+7 -> 45999.658 | M24: =L24+7 -> 46006.658 | N24: =M24+7 -> 46013.658 | ... BE24: =BD24+7 -> 46314.658
B25: =G13&" TARGET" -> Select the primary KPI (Jonas Library) TARGET
B26: Actual
B27: Delta | F27: =F26-F25 -> 0 | G27: =G26-G25 -> 0 | H27: =H26-H25 -> 0 | I27: =I26-I25 -> 0 | J27: =J26-J25 -> 0 | K27: =K26-K25 -> 0 | L27: =L26-L25 -> 0 | M27: =M26-M25 -> 0 | ... BE27: =BE26-BE25 -> 0
B29: =P13&" TARGET" -> Select the primary KPI (Jonas Library) TARGET
B30: Actual
B31: Delta | F31: =F30-F29 -> 0 | G31: =G30-G29 -> 0 | H31: =H30-H29 -> 0 | I31: =I30-I29 -> 0 | J31: =J30-J29 -> 0 | K31: =K30-K29 -> 0 | L31: =L30-L29 -> 0 | M31: =M30-M29 -> 0 | ... BE31: =BE30-BE29 -> 0
B33: =Y13&" TARGET" -> Select the primary KPI (Jonas Library) TARGET
B34: Actual
B35: Delta | F35: =F34-F33 -> 0 | G35: =G34-G33 -> 0 | H35: =H34-H33 -> 0 | I35: =I34-I33 -> 0 | J35: =J34-J33 -> 0 | K35: =K34-K33 -> 0 | L35: =L34-L33 -> 0 | M35: =M34-M33 -> 0 | ... BE35: =BE34-BE33 -> 0
B38: Revenue Target | F38: =IF($X$12="Revenue Impact",F33,0) -> 0 | G38: =IF($X$12="Revenue Impact",G33,0) -> 0 | H38: =IF($X$12="Revenue Impact",H33,0) -> 0 | I38: =IF($X$12="Revenue Impact",I33,0) -> 0 | J38: =IF($X$12="Revenue Impact",J33,0) -> 0 | K38: =IF($X$12="Revenue Impact",K33,0) -> 0 | L38: =IF($X$12="Revenue Impact",L33,0) -> 0 | M38: =IF($X$12="Revenue Impact",M33,0) -> 0 | ... BE38: =IF($X$12="Revenue Impact",BE33,0) -> 0
B39: Revenue Actual | F39: =IF($X$12="Revenue Impact",F34,0) -> 0 | G39: =IF($X$12="Revenue Impact",G34,0) -> 0 | H39: =IF($X$12="Revenue Impact",H34,0) -> 0 | I39: =IF($X$12="Revenue Impact",I34,0) -> 0 | J39: =IF($X$12="Revenue Impact",J34,0) -> 0 | K39: =IF($X$12="Revenue Impact",K34,0) -> 0 | L39: =IF($X$12="Revenue Impact",L34,0) -> 0 | M39: =IF($X$12="Revenue Impact",M34,0) -> 0 | ... BE39: =IF($X$12="Revenue Impact",BE34,0) -> 0
B41: Cost Target | F41: =IF($X$12="Cost Savings",F33,0) -> 0 | G41: =IF($X$12="Cost Savings",G33,0) -> 0 | H41: =IF($X$12="Cost Savings",H33,0) -> 0 | I41: =IF($X$12="Cost Savings",I33,0) -> 0 | J41: =IF($X$12="Cost Savings",J33,0) -> 0 | K41: =IF($X$12="Cost Savings",K33,0) -> 0 | L41: =IF($X$12="Cost Savings",L33,0) -> 0 | M41: =IF($X$12="Cost Savings",M33,0) -> 0 | ... BE41: =IF($X$12="Cost Savings",BE33,0) -> 0
B42: Cost Actual | F42: =IF($X$12="Cost Savings",F34,0) -> 0 | G42: =IF($X$12="Cost Savings",G34,0) -> 0 | H42: =IF($X$12="Cost Savings",H34,0) -> 0 | I42: =IF($X$12="Cost Savings",I34,0) -> 0 | J42: =IF($X$12="Cost Savings",J34,0) -> 0 | K42: =IF($X$12="Cost Savings",K34,0) -> 0 | L42: =IF($X$12="Cost Savings",L34,0) -> 0 | M42: =IF($X$12="Cost Savings",M34,0) -> 0 | ... BE42: =IF($X$12="Cost Savings",BE34,0) -> 0
B44: Financial Target | F44: =F38+F41 -> 0 | G44: =G38+G41 -> 0 | H44: =H38+H41 -> 0 | I44: =I38+I41 -> 0 | J44: =J38+J41 -> 0 | K44: =K38+K41 -> 0 | L44: =L38+L41 -> 0 | M44: =M38+M41 -> 0 | ... BE44: =BE38+BE41 -> 0
B45: Financial Actual | F45: =F39+F42 -> 0 | G45: =G39+G42 -> 0 | H45: =H39+H42 -> 0 | I45: =I39+I42 -> 0 | J45: =J39+J42 -> 0 | K45: =K39+K42 -> 0 | L45: =L39+L42 -> 0 | M45: =M39+M42 -> 0 | ... BE45: =BE39+BE42 -> 0
E46: To Date
B47: Current Financial Target | E47: =MAX(F47:BE47) -> 0 | F47: =IF($AZ$3>F24,F44,0) -> 0 | G47: =IF($AZ$3>G24,G44,0) -> 0 | H47: =IF($AZ$3>H24,H44,0) -> 0 | I47: =IF($AZ$3>I24,I44,0) -> 0 | J47: =IF($AZ$3>J24,J44,0) -> 0 | K47: =IF($AZ$3>K24,K44,0) -> 0 | L47: =IF($AZ$3>L24,L44,0) -> 0 | M47: =IF($AZ$3>M24,M44,0) -> 0 | ... BE47: =IF($AZ$3>BE24,BE44,0) -> 0
B48: Current Financial Actual | E48: =MAX(F48:BE48) -> 0 | F48: =IF($AZ$3>F25,F45,0) -> 0 | G48: =IF($AZ$3>G25,G45,0) -> 0 | H48: =IF($AZ$3>H25,H45,0) -> 0 | I48: =IF($AZ$3>I25,I45,0) -> 0 | J48: =IF($AZ$3>J25,J45,0) -> 0 | K48: =IF($AZ$3>K25,K45,0) -> 0 | L48: =IF($AZ$3>L25,L45,0) -> 0 | M48: =IF($AZ$3>M25,M45,0) -> 0 | ... BE48: =IF($AZ$3>BE25,BE45,0) -> 0

Sheet P3
B3: PROJECT | AG3: Strategic Value | AO3: =F8 | AV3: =IF(F7="",0,VLOOKUP(F7,Lookups!B12:H16,3)) -> 0 | AZ3: =NOW() -> 45957.658
AG4: Stage Multiplier (today) | AO4: =VLOOKUP(COUNTIF(AY10:BA21,"<="&AZ3),Table3357[],2) -> Not Def | AV4: =IF(AO4="Not Def",0,VLOOKUP(AO4,Lookups!L4:M8,2)) -> 0 | AZ4: Current Qtr | BC4: =VLOOKUP((YEAR(AZ3)&"-"&MONTH(AZ3)),Lookups!S3:U21,2) -> 2025-Q4
B5: Description (Use Case) | AG5: Stage Last Quarter | AO5: =VLOOKUP(COUNTIF(AY10:BA21,"<"&VLOOKUP(BC4,Lookups!W3:Y9,2)),Table3357[],2) -> Not Def | AQ5: =IF(AV5=1,"No Change","Progression") -> Progression | AV5: =IF(AO4="Not Def",0,IF(AO5=AO4,1,1.2)) -> 0
AG6: PROJECT SCORE | AV6: =AV3*AV4*AV5 -> 0
B7: Category | Y7: Ratio Impacted
B8: Strategic Value Level | F8: =IF(F7="","",VLOOKUP(F7,Lookups!B12:H16,2))
B9: Examples | F9: =IF(F7="","",VLOOKUP(F7,Lookups!B12:H16,4)) | AG9: Stage | AO9: Tasks | AV9: Target | AY9: Completed | BB9: Days to Target
AG10: Idea | AO10: Project Defined | BB10: =IF(AV10=$BK$3,"Missing Target",IF(AY10=$BK$3,IF($AZ$3>AV10,INT($AZ$3-AV10)&" Day(s) Overdue","Incomplete"),IF(AY10>AV10,INT(AY10-AV10)&" Day(s) Late",IF(AY10=AV10,"OK",INT(AV10-AY10)&" Day(s) Ahead")))) -> Missing Target
B11: PROJECT RESOURCES | F11: KEY PERFORMANCE INDICATORS / MEASURES OF SUCCESS | AO11: Business Case approved | BB11: =IF(AV11=$BK$3,"Missing Target",IF(AY11=$BK$3,IF($AZ$3>AV11,INT($AZ$3-AV11)&" Day(s) Overdue","Incomplete"),IF(AY11>AV11,INT(AY11-AV11)&" Day(s) Late",IF(AY11=AV11,"OK",INT(AV11-AY11)&" Day(s) Ahead")))) -> Missing Target
B12: AI Tools & Services | F12: =IF(F7="","",VLOOKUP(F7,Lookups!B12:H16,5)) | O12: =IF(F7="","",VLOOKUP(F7,Lookups!B12:H16,6)) | X12: =IF(F7="","",VLOOKUP(F7,Lookups!B12:H16,7)) | AO12: Resources Allocated | BB12: =IF(AV12=$BK$3,"Missing Target",IF(AY12=$BK$3,IF($AZ$3>AV12,INT($AZ$3-AV12)&" Day(s) Overdue","Incomplete"),IF(AY12>AV12,INT(AY12-AV12)&" Day(s) Late",IF(AY12=AV12,"OK",INT(AV12-AY12)&" Day(s) Ahead")))) -> Missing Target
F13: KPI | G13: Select the primary KPI (Jonas Library) | O13: KPI | P13: Select the primary KPI (Jonas Library) | X13: KPI | Y13: Select the primary KPI (Jonas Library) | AG13: Develop | AO13: Technical PoC validated | BB13: =IF(AV13=$BK$3,"Missing Target",IF(AY13=$BK$3,IF($AZ$3>AV13,INT($AZ$3-AV13)&" Day(s) Overdue","Incomplete"),IF(AY13>AV13,INT(AY13-AV13)&" Day(s) Late",IF(AY13=AV13,"OK",INT(AV13-AY13)&" Day(s) Ahead")))) -> Missing Target
F14: How does this Project support this KPI? | O14: How does this Project support this KPI? | X14: How does this Project support this KPI? | AO14: Dev roadmap documented | BB14: =IF(AV14=$BK$3,"Missing Target",IF(AY14=$BK$3,IF($AZ$3>AV14,INT($AZ$3-AV14)&" Day(s) Overdue","Incomplete"),IF(AY14>AV14,INT(AY14-AV14)&" Day(s) Late",IF(AY14=AV14,"OK",INT(AV14-AY14)&" Day(s) Ahead")))) -> Missing Target
AO15: Coding started | BB15: =IF(AV15=$A$1,"Missing Target",IF(AY15=$A$1,IF($AZ$3>AV15,INT($AZ$3-AV15)&" Day(s) Overdue","Incomplete"),IF(AY15>AV15,INT(AY15-AV15)&" Day(s) Late",IF(AY15=AV15,"OK",INT(AV15-AY15)&" Day(s) Ahead")))) -> Missing Target
AG16: Pilot | AO16: Deployment to beta | BB16: =IF(AV16=$A$1,"Missing Target",IF(AY16=$A$1,IF($AZ$3>AV16,INT($AZ$3-AV16)&" Day(s) Overdue","Incomplete"),IF(AY16>AV16,INT(AY16-AV16)&" Day(s) Late",IF(AY16=AV16,"OK",INT(AV16-AY16)&" Day(s) Ahead")))) -> Missing Target
B17: Contact | AO17: Initial metrics/feedback | BB17: =IF(AV17=$A$1,"Missing Target",IF(AY17=$A$1,IF($AZ$3>AV17,INT($AZ$3-AV17)&" Day(s) Overdue","Incomplete"),IF(AY17>AV17,INT(AY17-AV17)&" Day(s) Late",IF(AY17=AV17,"OK",INT(AV17-AY17)&" Day(s) Ahead")))) -> Missing Target
B18: Prod Mgr | F18: How will you measure the KPI? | O18: How will you measure the KPI? | X18: How will you measure the KPI? | AO18: Feedback affecting code | BB18: =IF(AV18=$A$1,"Missing Target",IF(AY18=$A$1,IF($AZ$3>AV18,INT($AZ$3-AV18)&" Day(s) Overdue","Incomplete"),IF(AY18>AV18,INT(AY18-AV18)&" Day(s) Late",IF(AY18=AV18,"OK",INT(AV18-AY18)&" Day(s) Ahead")))) -> Missing Target
B19: Analyst | AG19: Live | AO19: General release available | BB19: =IF(AV19=$A$1,"Missing Target",IF(AY19=$A$1,IF($AZ$3>AV19,INT($AZ$3-AV19)&" Day(s) Overdue","Incomplete"),IF(AY19>AV19,INT(AY19-AV19)&" Day(s) Late",IF(AY19=AV19,"OK",INT(AV19-AY19)&" Day(s) Ahead")))) -> Missing Target
B20: Tech Lead | AO20: Success mertics tracking | BB20: =IF(AV20=$A$1,"Missing Target",IF(AY20=$A$1,IF($AZ$3>AV20,INT($AZ$3-AV20)&" Day(s) Overdue","Incomplete"),IF(AY20>AV20,INT(AY20-AV20)&" Day(s) Late",IF(AY20=AV20,"OK",INT(AV20-AY20)&" Day(s) Ahead")))) -> Missing Target
B21: Exec | AO21: Feedback loop continuing | BB21: =IF(AV21=$A$1,"Missing Target",IF(AY21=$A$1,IF($AZ$3>AV21,INT($AZ$3-AV21)&" Day(s) Overdue","Incomplete"),IF(AY21>AV21,INT(AY21-AV21)&" Day(s) Late",IF(AY21=AV21,"OK",INT(AV21-AY21)&" Day(s) Ahead")))) -> Missing Target
B23: WEEKLY KPI TRACKER | F23: 1 | G23: =F23+1 -> 2 | H23: =G23+1 -> 3 | I23: =H23+1 -> 4 | J23: =I23+1 -> 5 | K23: =J23+1 -> 6 | L23: =K23+1 -> 7 | M23: =L23+1 -> 8 | N23: =M23+1 -> 9 | ... BE23: =BD23+1 -> 52
B24: Week Ending | F24: =NOW() -> 45957.658 | G24: =F24+7 -> 45964.658 | H24: =G24+7 -> 45971.658 | I24: =H24+7 -> 45978.658 | J24: =I24+7 -> 45985.658 | K24: =J24+7 -> 45992.658 | L24: =K24+7 -> 45999.658 | M24: =L24+7 -> 46006.658 | N24: =M24+7 -> 46013.658 | ... BE24: =BD24+7 -> 46314.658
B25: =G13&" TARGET" -> Select the primary KPI (Jonas Library) TARGET
B26: Actual
B27: Delta | F27: =F26-F25 -> 0 | G27: =G26-G25 -> 0 | H27: =H26-H25 -> 0 | I27: =I26-I25 -> 0 | J27: =J26-J25 -> 0 | K27: =K26-K25 -> 0 | L27: =L26-L25 -> 0 | M27: =M26-M25 -> 0 | ... BE27: =BE26-BE25 -> 0
B29: =P13&" TARGET" -> Select the primary KPI (Jonas Library) TARGET
B30: Actual
B31: Delta | F31: =F30-F29 -> 0 | G31: =G30-G29 -> 0 | H31: =H30-H29 -> 0 | I31: =I30-I29 -> 0 | J31: =J30-J29 -> 0 | K31: =K30-K29 -> 0 | L31: =L30-L29 -> 0 | M31: =M30-M29 -> 0 | ... BE31: =BE30-BE29 -> 0
B33: =Y13&" TARGET" -> Select the primary KPI (Jonas Library) TARGET
B34: Actual
B35: Delta | F35: =F34-F33 -> 0 | G35: =G34-G33 -> 0 | H35: =H34-H33 -> 0 | I35: =I34-I33 -> 0 | J35: =J34-J33 -> 0 | K35: =K34-K33 -> 0 | L35: =L34-L33 -> 0 | M35: =M34-M33 -> 0 | ... BE35: =BE34-BE33 -> 0
B38: Revenue Target | F38: =IF($X$12="Revenue Impact",F33,0) -> 0 | G38: =IF($X$12="Revenue Impact",G33,0) -> 0 | H38: =IF($X$12="Revenue Impact",H33,0) -> 0 | I38: =IF($X$12="Revenue Impact",I33,0) -> 0 | J38: =IF($X$12="Revenue Impact",J33,0) -> 0 | K38: =IF($X$12="Revenue Impact",K33,0) -> 0 | L38: =IF($X$12="Revenue Impact",L33,0) -> 0 | M38: =IF($X$12="Revenue Impact",M33,0) -> 0 | ... BE38: =IF($X$12="Revenue Impact",BE33,0) -> 0
B39: Revenue Actual | F39: =IF($X$12="Revenue Impact",F34,0) -> 0 | G39: =IF($X$12="Revenue Impact",G34,0) -> 0 | H39: =IF($X$12="Revenue Impact",H34,0) -> 0 | I39: =IF($X$12="Revenue Impact",I34,0) -> 0 | J39: =IF($X$12="Revenue Impact",J34,0) -> 0 | K39: =IF($X$12="Revenue Impact",K34,0) -> 0 | L39: =IF($X$12="Revenue Impact",L34,0) -> 0 | M39: =IF($X$12="Revenue Impact",M34,0) -> 0 | ... BE39: =IF($X$12="Revenue Impact",BE34,0) -> 0
B41: Cost Target | F41: =IF($X$12="Cost Savings",F33,0) -> 0 | G41: =IF($X$12="Cost Savings",G33,0) -> 0 | H41: =IF($X$12="Cost Savings",H33,0) -> 0 | I41: =IF($X$12="Cost Savings",I33,0) -> 0 | J41: =IF($X$12="Cost Savings",J33,0) -> 0 | K41: =IF($X$12="Cost Savings",K33,0) -> 0 | L41: =IF($X$12="Cost Savings",L33,0) -> 0 | M41: =IF($X$12="Cost Savings",M33,0) -> 0 | ... BE41: =IF($X$12="Cost Savings",BE33,0) -> 0
B42: Cost Actual | F42: =IF($X$12="Cost Savings",F34,0) -> 0 | G42: =IF($X$12="Cost Savings",G34,0) -> 0 | H42: =IF($X$12="Cost Savings",H34,0) -> 0 | I42: =IF($X$12="Cost Savings",I34,0) -> 0 | J42: =IF($X$12="Cost Savings",J34,0) -> 0 | K42: =IF($X$12="Cost Savings",K34,0) -> 0 | L42: =IF($X$12="Cost Savings",L34,0) -> 0 | M42: =IF($X$12="Cost Savings",M34,0) -> 0 | ... BE42: =IF($X$12="Cost Savings",BE34,0) -> 0
B44: Financial Target | F44: =F38+F41 -> 0 | G44: =G38+G41 -> 0 | H44: =H38+H41 -> 0 | I44: =I38+I41 -> 0 | J44: =J38+J41 -> 0 | K44: =K38+K41 -> 0 | L44: =L38+L41 -> 0 | M44: =M38+M41 -> 0 | ... BE44: =BE38+BE41 -> 0
B45: Financial Actual | F45: =F39+F42 -> 0 | G45: =G39+G42 -> 0 | H45: =H39+H42 -> 0 | I45: =I39+I42 -> 0 | J45: =J39+J42 -> 0 | K45: =K39+K42 -> 0 | L45: =L39+L42 -> 0 | M45: =M39+M42 -> 0 | ... BE45: =BE39+BE42 -> 0
E46: To Date
B47: Current Financial Target | E47: =MAX(F47:BE47) -> 0 | F47: =IF($AZ$3>F24,F44,0) -> 0 | G47: =IF($AZ$3>G24,G44,0) -> 0 | H47: =IF($AZ$3>H24,H44,0) -> 0 | I47: =IF($AZ$3>I24,I44,0) -> 0 | J47: =IF($AZ$3>J24,J44,0) -> 0 | K47: =IF($AZ$3>K24,K44,0) -> 0 | L47: =IF($AZ$3>L24,L44,0) -> 0 | M47: =IF($AZ$3>M24,M44,0) -> 0 | ... BE47: =IF($AZ$3>BE24,BE44,0) -> 0
B48: Current Financial Actual | E48: =MAX(F48:BE48) -> 0 | F48: =IF($AZ$3>F25,F45,0) -> 0 | G48: =IF($AZ$3>G25,G45,0) -> 0 | H48: =IF($AZ$3>H25,H45,0) -> 0 | I48: =IF($AZ$3>I25,I45,0) -> 0 | J48: =IF($AZ$3>J25,J45,0) -> 0 | K48: =IF($AZ$3>K25,K45,0) -> 0 | L48: =IF($AZ$3>L25,L45,0) -> 0 | M48: =IF($AZ$3>M25,M45,0) -> 0 | ... BE48: =IF($AZ$3>BE25,BE45,0) -> 0

Sheet P4
B3: PROJECT | AG3: Strategic Value | AO3: =F8 | AV3: =IF(F7="",0,VLOOKUP(F7,Lookups!B12:H16,3)) -> 0 | AZ3: =NOW() -> 45957.658
AG4: Stage Multiplier (today) | AO4: =VLOOKUP(COUNTIF(AY10:BA21,"<="&AZ3),Table3357[],2) -> Not Def | AV4: =IF(AO4="Not Def",0,VLOOKUP(AO4,Lookups!L4:M8,2)) -> 0 | AZ4: Current Qtr | BC4: =VLOOKUP((YEAR(AZ3)&"-"&MONTH(AZ3)),Lookups!S3:U21,2) -> 2025-Q4
B5: Description (Use Case) | AG5: Stage Last Quarter | AO5: =VLOOKUP(COUNTIF(AY10:BA21,"<"&VLOOKUP(BC4,Lookups!W3:Y9,2)),Table3357[],2) -> Not Def | AQ5: =IF(AV5=1,"No Change","Progression") -> Progression | AV5: =IF(AO4="Not Def",0,IF(AO5=AO4,1,1.2)) -> 0
AG6: PROJECT SCORE | AV6: =AV3*AV4*AV5 -> 0
B7: Category | Y7: Ratio Impacted
B8: Strategic Value Level | F8: =IF(F7="","",VLOOKUP(F7,Lookups!B12:H16,2))
B9: Examples | F9: =IF(F7="","",VLOOKUP(F7,Lookups!B12:H16,4)) | AG9: Stage | AO9: Tasks | AV9: Target | AY9: Completed | BB9: Days to Target
AG10: Idea | AO10: Project Defined | BB10: =IF(AV10=$BK$3,"Missing Target",IF(AY10=$BK$3,IF($AZ$3>AV10,INT($AZ$3-AV10)&" Day(s) Overdue","Incomplete"),IF(AY10>AV10,INT(AY10-AV10)&" Day(s) Late",IF(AY10=AV10,"OK",INT(AV10-AY10)&" Day(s) Ahead")))) -> Missing Target
B11: PROJECT RESOURCES | F11: KEY PERFORMANCE INDICATORS / MEASURES OF SUCCESS | AO11: Business Case approved | BB11: =IF(AV11=$BK$3,"Missing Target",IF(AY11=$BK$3,IF($AZ$3>AV11,INT($AZ$3-AV11)&" Day(s) Overdue","Incomplete"),IF(AY11>AV11,INT(AY11-AV11)&" Day(s) Late",IF(AY11=AV11,"OK",INT(AV11-AY11)&" Day(s) Ahead")))) -> Missing Target
B12: AI Tools & Services | F12: =IF(F7="","",VLOOKUP(F7,Lookups!B12:H16,5)) | O12: =IF(F7="","",VLOOKUP(F7,Lookups!B12:H16,6)) | X12: =IF(F7="","",VLOOKUP(F7,Lookups!B12:H16,7)) | AO12: Resources Allocated | BB12: =IF(AV12=$BK$3,"Missing Target",IF(AY12=$BK$3,IF($AZ$3>AV12,INT($AZ$3-AV12)&" Day(s) Overdue","Incomplete"),IF(AY12>AV12,INT(AY12-AV12)&" Day(s) Late",IF(AY12=AV12,"OK",INT(AV12-AY12)&" Day(s) Ahead")))) -> Missing Target
F13: KPI | G13: Select the primary KPI (Jonas Library) | O13: KPI | P13: Select the primary KPI (Jonas Library) | X13: KPI | Y13: Select the primary KPI (Jonas Library) | AG13: Develop | AO13: Technical PoC validated | BB13: =IF(AV13=$BK$3,"Missing Target",IF(AY13=$BK$3,IF($AZ$3>AV13,INT($AZ$3-AV13)&" Day(s) Overdue","Incomplete"),IF(AY13>AV13,INT(AY13-AV13)&" Day(s) Late",IF(AY13=AV13,"OK",INT(AV13-AY13)&" Day(s) Ahead")))) -> Missing Target
F14: How does this Project support this KPI? | O14: How does this Project support this KPI? | X14: How does this Project support this KPI? | AO14: Dev roadmap documented | BB14: =IF(AV14=$BK$3,"Missing Target",IF(AY14=$BK$3,IF($AZ$3>AV14,INT($AZ$3-AV14)&" Day(s) Overdue","Incomplete"),IF(AY14>AV14,INT(AY14-AV14)&" Day(s) Late",IF(AY14=AV14,"OK",INT(AV14-AY14)&" Day(s) Ahead")))) -> Missing Target
AO15: Coding started | BB15: =IF(AV15=$A$1,"Missing Target",IF(AY15=$A$1,IF($AZ$3>AV15,INT($AZ$3-AV15)&" Day(s) Overdue","Incomplete"),IF(AY15>AV15,INT(AY15-AV15)&" Day(s) Late",IF(AY15=AV15,"OK",INT(AV15-AY15)&" Day(s) Ahead")))) -> Missing Target
AG16: Pilot | AO16: Deployment to beta | BB16: =IF(AV16=$A$1,"Missing Target",IF(AY16=$A$1,IF($AZ$3>AV16,INT($AZ$3-AV16)&" Day(s) Overdue","Incomplete"),IF(AY16>AV16,INT(AY16-AV16)&" Day(s) Late",IF(AY16=AV16,"OK",INT(AV16-AY16)&" Day(s) Ahead")))) -> Missing Target
B17: Contact | AO17: Initial metrics/feedback | BB17: =IF(AV17=$A$1,"Missing Target",IF(AY17=$A$1,IF($AZ$3>AV17,INT($AZ$3-AV17)&" Day(s) Overdue","Incomplete"),IF(AY17>AV17,INT(AY17-AV17)&" Day(s) Late",IF(AY17=AV17,"OK",INT(AV17-AY17)&" Day(s) Ahead")))) -> Missing Target
B18: Prod Mgr | F18: How will you measure the KPI? | O18: How will you measure the KPI? | X18: How will you measure the KPI? | AO18: Feedback affecting code | BB18: =IF(AV18=$A$1,"Missing Target",IF(AY18=$A$1,IF($AZ$3>AV18,INT($AZ$3-AV18)&" Day(s) Overdue","Incomplete"),IF(AY18>AV18,INT(AY18-AV18)&" Day(s) Late",IF(AY18=AV18,"OK",INT(AV18-AY18)&" Day(s) Ahead")))) -> Missing Target
B19: Analyst | AG19: Live | AO19: General release available | BB19: =IF(AV19=$A$1,"Missing Target",IF(AY19=$A$1,IF($AZ$3>AV19,INT($AZ$3-AV19)&" Day(s) Overdue","Incomplete"),IF(AY19>AV19,INT(AY19-AV19)&" Day(s) Late",IF(AY19=AV19,"OK",INT(AV19-AY19)&" Day(s) Ahead")))) -> Missing Target
B20: Tech Lead | AO20: Success mertics tracking | BB20: =IF(AV20=$A$1,"Missing Target",IF(AY20=$A$1,IF($AZ$3>AV20,INT($AZ$3-AV20)&" Day(s) Overdue","Incomplete"),IF(AY20>AV20,INT(AY20-AV20)&" Day(s) Late",IF(AY20=AV20,"OK",INT(AV20-AY20)&" Day(s) Ahead")))) -> Missing Target
B21: Exec | AO21: Feedback loop continuing | BB21: =IF(AV21=$A$1,"Missing Target",IF(AY21=$A$1,IF($AZ$3>AV21,INT($AZ$3-AV21)&" Day(s) Overdue","Incomplete"),IF(AY21>AV21,INT(AY21-AV21)&" Day(s) Late",IF(AY21=AV21,"OK",INT(AV21-AY21)&" Day(s) Ahead")))) -> Missing Target
B23: WEEKLY KPI TRACKER | F23: 1 | G23: =F23+1 -> 2 | H23: =G23+1 -> 3 | I23: =H23+1 -> 4 | J23: =I23+1 -> 5 | K23: =J23+1 -> 6 | L23: =K23+1 -> 7 | M23: =L23+1 -> 8 | N23: =M23+1 -> 9 | ... BE23: =BD23+1 -> 52
B24: Week Ending | F24: =NOW() -> 45957.658 | G24: =F24+7 -> 45964.658 | H24: =G24+7 -> 45971.658 | I24: =H24+7 -> 45978.658 | J24: =I24+7 -> 45985.658 | K24: =J24+7 -> 45992.658 | L24: =K24+7 -> 45999.658 | M24: =L24+7 -> 46006.658 | N24: =M24+7 -> 46013.658 | ... BE24: =BD24+7 -> 46314.658
B25: =G13&" TARGET" -> Select the primary KPI (Jonas Library) TARGET
B26: Actual
B27: Delta | F27: =F26-F25 -> 0 | G27: =G26-G25 -> 0 | H27: =H26-H25 -> 0 | I27: =I26-I25 -> 0 | J27: =J26-J25 -> 0 | K27: =K26-K25 -> 0 | L27: =L26-L25 -> 0 | M27: =M26-M25 -> 0 | ... BE27: =BE26-BE25 -> 0
B29: =P13&" TARGET" -> Select the primary KPI (Jonas Library) TARGET
B30: Actual
B31: Delta | F31: =F30-F29 -> 0 | G31: =G30-G29 -> 0 | H31: =H30-H29 -> 0 | I31: =I30-I29 -> 0 | J31: =J30-J29 -> 0 | K31: =K30-K29 -> 0 | L31: =L30-L29 -> 0 | M31: =M30-M29 -> 0 | ... BE31: =BE30-BE29 -> 0
B33: =Y13&" TARGET" -> Select the primary KPI (Jonas Library) TARGET
B34: Actual
B35: Delta | F35: =F34-F33 -> 0 | G35: =G34-G33 -> 0 | H35: =H34-H33 -> 0 | I35: =I34-I33 -> 0 | J35: =J34-J33 -> 0 | K35: =K34-K33 -> 0 | L35: =L34-L33 -> 0 | M35: =M34-M33 -> 0 | ... BE35: =BE34-BE33 -> 0
B38: Revenue Target | F38: =IF($X$12="Revenue Impact",F33,0) -> 0 | G38: =IF($X$12="Revenue Impact",G33,0) -> 0 | H38: =IF($X$12="Revenue Impact",H33,0) -> 0 | I38: =IF($X$12="Revenue Impact",I33,0) -> 0 | J38: =IF($X$12="Revenue Impact",J33,0) -> 0 | K38: =IF($X$12="Revenue Impact",K33,0) -> 0 | L38: =IF($X$12="Revenue Impact",L33,0) -> 0 | M38: =IF($X$12="Revenue Impact",M33,0) -> 0 | ... BE38: =IF($X$12="Revenue Impact",BE33,0) -> 0
B39: Revenue Actual | F39: =IF($X$12="Revenue Impact",F34,0) -> 0 | G39: =IF($X$12="Revenue Impact",G34,0) -> 0 | H39: =IF($X$12="Revenue Impact",H34,0) -> 0 | I39: =IF($X$12="Revenue Impact",I34,0) -> 0 | J39: =IF($X$12="Revenue Impact",J34,0) -> 0 | K39: =IF($X$12="Revenue Impact",K34,0) -> 0 | L39: =IF($X$12="Revenue Impact",L34,0) -> 0 | M39: =IF($X$12="Revenue Impact",M34,0) -> 0 | ... BE39: =IF($X$12="Revenue Impact",BE34,0) -> 0
B41: Cost Target | F41: =IF($X$12="Cost Savings",F33,0) -> 0 | G41: =IF($X$12="Cost Savings",G33,0) -> 0 | H41: =IF($X$12="Cost Savings",H33,0) -> 0 | I41: =IF($X$12="Cost Savings",I33,0) -> 0 | J41: =IF($X$12="Cost Savings",J33,0) -> 0 | K41: =IF($X$12="Cost Savings",K33,0) -> 0 | L41: =IF($X$12="Cost Savings",L33,0) -> 0 | M41: =IF($X$12="Cost Savings",M33,0) -> 0 | ... BE41: =IF($X$12="Cost Savings",BE33,0) -> 0
B42: Cost Actual | F42: =IF($X$12="Cost Savings",F34,0) -> 0 | G42: =IF($X$12="Cost Savings",G34,0) -> 0 | H42: =IF($X$12="Cost Savings",H34,0) -> 0 | I42: =IF($X$12="Cost Savings",I34,0) -> 0 | J42: =IF($X$12="Cost Savings",J34,0) -> 0 | K42: =IF($X$12="Cost Savings",K34,0) -> 0 | L42: =IF($X$12="Cost Savings",L34,0) -> 0 | M42: =IF($X$12="Cost Savings",M34,0) -> 0 | ... BE42: =IF($X$12="Cost Savings",BE34,0) -> 0
B44: Financial Target | F44: =F38+F41 -> 0 | G44: =G38+G41 -> 0 | H44: =H38+H41 -> 0 | I44: =I38+I41 -> 0 | J44: =J38+J41 -> 0 | K44: =K38+K41 -> 0 | L44: =L38+L41 -> 0 | M44: =M38+M41 -> 0 | ... BE44: =BE38+BE41 -> 0
B45: Financial Actual | F45: =F39+F42 -> 0 | G45: =G39+G42 -> 0 | H45: =H39+H42 -> 0 | I45: =I39+I42 -> 0 | J45: =J39+J42 -> 0 | K45: =K39+K42 -> 0 | L45: =L39+L42 -> 0 | M45: =M39+M42 -> 0 | ... BE45: =BE39+BE42 -> 0
E46: To Date
B47: Current Financial Target | E47: =MAX(F47:BE47) -> 0 | F47: =IF($AZ$3>F24,F44,0) -> 0 | G47: =IF($AZ$3>G24,G44,0) -> 0 | H47: =IF($AZ$3>H24,H44,0) -> 0 | I47: =IF($AZ$3>I24,I44,0) -> 0 | J47: =IF($AZ$3>J24,J44,0) -> 0 | K47: =IF($AZ$3>K24,K44,0) -> 0 | L47: =IF($AZ$3>L24,L44,0) -> 0 | M47: =IF($AZ$3>M24,M44,0) -> 0 | ... BE47: =IF($AZ$3>BE24,BE44,0) -> 0
B48: Current Financial Actual | E48: =MAX(F48:BE48) -> 0 | F48: =IF($AZ$3>F25,F45,0) -> 0 | G48: =IF($AZ$3>G25,G45,0) -> 0 | H48: =IF($AZ$3>H25,H45,0) -> 0 | I48: =IF($AZ$3>I25,I45,0) -> 0 | J48: =IF($AZ$3>J25,J45,0) -> 0 | K48: =IF($AZ$3>K25,K45,0) -> 0 | L48: =IF($AZ$3>L25,L45,0) -> 0 | M48: =IF($AZ$3>M25,M45,0) -> 0 | ... BE48: =IF($AZ$3>BE25,BE45,0) -> 0

Sheet P5
B3: PROJECT | AG3: Strategic Value | AO3: =F8 | AV3: =IF(F7="",0,VLOOKUP(F7,Lookups!B12:H16,3)) -> 0 | AZ3: =NOW() -> 45957.658
AG4: Stage Multiplier (today) | AO4: =VLOOKUP(COUNTIF(AY10:BA21,"<="&AZ3),Table3357[],2) -> Not Def | AV4: =IF(AO4="Not Def",0,VLOOKUP(AO4,Lookups!L4:M8,2)) -> 0 | AZ4: Current Qtr | BC4: =VLOOKUP((YEAR(AZ3)&"-"&MONTH(AZ3)),Lookups!S3:U21,2) -> 2025-Q4
B5: Description (Use Case) | AG5: Stage Last Quarter | AO5: =VLOOKUP(COUNTIF(AY10:BA21,"<"&VLOOKUP(BC4,Lookups!W3:Y9,2)),Table3357[],2) -> Not Def | AQ5: =IF(AV5=1,"No Change","Progression") -> Progression | AV5: =IF(AO4="Not Def",0,IF(AO5=AO4,1,1.2)) -> 0
AG6: PROJECT SCORE | AV6: =AV3*AV4*AV5 -> 0
B7: Category | Y7: Ratio Impacted
B8: Strategic Value Level | F8: =IF(F7="","",VLOOKUP(F7,Lookups!B12:H16,2))
B9: Examples | F9: =IF(F7="","",VLOOKUP(F7,Lookups!B12:H16,4)) | AG9: Stage | AO9: Tasks | AV9: Target | AY9: Completed | BB9: Days to Target
AG10: Idea | AO10: Project Defined | BB10: =IF(AV10=$BK$3,"Missing Target",IF(AY10=$BK$3,IF($AZ$3>AV10,INT($AZ$3-AV10)&" Day(s) Overdue","Incomplete"),IF(AY10>AV10,INT(AY10-AV10)&" Day(s) Late",IF(AY10=AV10,"OK",INT(AV10-AY10)&" Day(s) Ahead")))) -> Missing Target
B11: PROJECT RESOURCES | F11: KEY PERFORMANCE INDICATORS / MEASURES OF SUCCESS | AO11: Business Case approved | BB11: =IF(AV11=$BK$3,"Missing Target",IF(AY11=$BK$3,IF($AZ$3>AV11,INT($AZ$3-AV11)&" Day(s) Overdue","Incomplete"),IF(AY11>AV11,INT(AY11-AV11)&" Day(s) Late",IF(AY11=AV11,"OK",INT(AV11-AY11)&" Day(s) Ahead")))) -> Missing Target
B12: AI Tools & Services | F12: =IF(F7="","",VLOOKUP(F7,Lookups!B12:H16,5)) | O12: =IF(F7="","",VLOOKUP(F7,Lookups!B12:H16,6)) | X12: =IF(F7="","",VLOOKUP(F7,Lookups!B12:H16,7)) | AO12: Resources Allocated | BB12: =IF(AV12=$BK$3,"Missing Target",IF(AY12=$BK$3,IF($AZ$3>AV12,INT($AZ$3-AV12)&" Day(s) Overdue","Incomplete"),IF(AY12>AV12,INT(AY12-AV12)&" Day(s) Late",IF(AY12=AV12,"OK",INT(AV12-AY12)&" Day(s) Ahead")))) -> Missing Target
F13: KPI | G13: Select the primary KPI (Jonas Library) | O13: KPI | P13: Select the primary KPI (Jonas Library) | X13: KPI | Y13: Select the primary KPI (Jonas Library) | AG13: Develop | AO13: Technical PoC validated | BB13: =IF(AV13=$BK$3,"Missing Target",IF(AY13=$BK$3,IF($AZ$3>AV13,INT($AZ$3-AV13)&" Day(s) Overdue","Incomplete"),IF(AY13>AV13,INT(AY13-AV13)&" Day(s) Late",IF(AY13=AV13,"OK",INT(AV13-AY13)&" Day(s) Ahead")))) -> Missing Target
F14: How does this Project support this KPI? | O14: How does this Project support this KPI? | X14: How does this Project support this KPI? | AO14: Dev roadmap documented | BB14: =IF(AV14=$BK$3,"Missing Target",IF(AY14=$BK$3,IF($AZ$3>AV14,INT($AZ$3-AV14)&" Day(s) Overdue","Incomplete"),IF(AY14>AV14,INT(AY14-AV14)&" Day(s) Late",IF(AY14=AV14,"OK",INT(AV14-AY14)&" Day(s) Ahead")))) -> Missing Target
AO15: Coding started | BB15: =IF(AV15=$A$1,"Missing Target",IF(AY15=$A$1,IF($AZ$3>AV15,INT($AZ$3-AV15)&" Day(s) Overdue","Incomplete"),IF(AY15>AV15,INT(AY15-AV15)&" Day(s) Late",IF(AY15=AV15,"OK",INT(AV15-AY15)&" Day(s) Ahead")))) -> Missing Target
AG16: Pilot | AO16: Deployment to beta | BB16: =IF(AV16=$A$1,"Missing Target",IF(AY16=$A$1,IF($AZ$3>AV16,INT($AZ$3-AV16)&" Day(s) Overdue","Incomplete"),IF(AY16>AV16,INT(AY16-AV16)&" Day(s) Late",IF(AY16=AV16,"OK",INT(AV16-AY16)&" Day(s) Ahead")))) -> Missing Target
B17: Contact | AO17: Initial metrics/feedback | BB17: =IF(AV17=$A$1,"Missing Target",IF(AY17=$A$1,IF($AZ$3>AV17,INT($AZ$3-AV17)&" Day(s) Overdue","Incomplete"),IF(AY17>AV17,INT(AY17-AV17)&" Day(s) Late",IF(AY17=AV17,"OK",INT(AV17-AY17)&" Day(s) Ahead")))) -> Missing Target
B18: Prod Mgr | F18: How will you measure the KPI? | O18: How will you measure the KPI? | X18: How will you measure the KPI? | AO18: Feedback affecting code | BB18: =IF(AV18=$A$1,"Missing Target",IF(AY18=$A$1,IF($AZ$3>AV18,INT($AZ$3-AV18)&" Day(s) Overdue","Incomplete"),IF(AY18>AV18,INT(AY18-AV18)&" Day(s) Late",IF(AY18=AV18,"OK",INT(AV18-AY18)&" Day(s) Ahead")))) -> Missing Target
B19: Analyst | AG19: Live | AO19: General release available | BB19: =IF(AV19=$A$1,"Missing Target",IF(AY19=$A$1,IF($AZ$3>AV19,INT($AZ$3-AV19)&" Day(s) Overdue","Incomplete"),IF(AY19>AV19,INT(AY19-AV19)&" Day(s) Late",IF(AY19=AV19,"OK",INT(AV19-AY19)&" Day(s) Ahead")))) -> Missing Target
B20: Tech Lead | AO20: Success mertics tracking | BB20: =IF(AV20=$A$1,"Missing Target",IF(AY20=$A$1,IF($AZ$3>AV20,INT($AZ$3-AV20)&" Day(s) Overdue","Incomplete"),IF(AY20>AV20,INT(AY20-AV20)&" Day(s) Late",IF(AY20=AV20,"OK",INT(AV20-AY20)&" Day(s) Ahead")))) -> Missing Target
B21: Exec | AO21: Feedback loop continuing | BB21: =IF(AV21=$A$1,"Missing Target",IF(AY21=$A$1,IF($AZ$3>AV21,INT($AZ$3-AV21)&" Day(s) Overdue","Incomplete"),IF(AY21>AV21,INT(AY21-AV21)&" Day(s) Late",IF(AY21=AV21,"OK",INT(AV21-AY21)&" Day(s) Ahead")))) -> Missing Target
B23: WEEKLY KPI TRACKER | F23: 1 | G23: =F23+1 -> 2 | H23: =G23+1 -> 3 | I23: =H23+1 -> 4 | J23: =I23+1 -> 5 | K23: =J23+1 -> 6 | L23: =K23+1 -> 7 | M23: =L23+1 -> 8 | N23: =M23+1 -> 9 | ... BE23: =BD23+1 -> 52
